Workbook
Name Автомобильная_техника: #REF!
Name Боевые_машины: #REF!
Name бп: Таблица9[Столбец1]
Name БПЛА: #REF!
Name Бронеавтомобили_и_MRAP: #REF!
Name Буксируемая_артиллерия: #REF!
Name дроны: Таблица2[Столбец1]
Name Инженерная_техника: #REF!
Name Инженерные_сооружения: #REF!
Name Личный_состав: '[1]Справочная информация'!$C$2:$C$3
Name Надводные_суда: #REF!
Name Общий___Центр: #REF!
Name Переносные_ударные_системы: #REF!
Name подразделения: Таблица1[Столбец1]
Name расчет: Таблица3[Столбец1]
Name расчеты: 'Нетрогать '!$A$5:$A$59
Name Самоходная_артиллерия: #REF!
Name Системы_залпового_огня: #REF!
Name Системы_ПВО: #REF!
Name Системы_связи: #REF!
Name Танк: #REF!
Name Танки: #REF!
Name уточнение: #REF!
Name характер: Таблица4[Столбец1]
Name цель: #REF!
Name Автомобильная_техника: #REF!
Name Боевые_машины: #REF!
Name бп: 'C:\Users\rvolo\OneDrive\Рабочий стол\Работа с ИБД\ИД отряда (Ю) от 25.05.25.xlsx'!Таблица9[Столбец1]
Name БПЛА: #REF!
Name Бронеавтомобили_и_MRAP: #REF!
Name Буксируемая_артиллерия: #REF!
Name дроны: 'C:\Users\rvolo\OneDrive\Рабочий стол\Работа с ИБД\ИД отряда (Ю) от 25.05.25.xlsx'!Таблица2[Столбец1]
Name Инженерная_техника: #REF!
Name Инженерные_сооружения: #REF!
Name Надводные_суда: #REF!
Name Общий___Центр: #REF!
Name Переносные_ударные_системы: #REF!
Name подразделения: 'C:\Users\rvolo\OneDrive\Рабочий стол\Работа с ИБД\ИД отряда (Ю) от 25.05.25.xlsx'!Таблица1[Столбец1]
Name расчет: 'C:\Users\rvolo\OneDrive\Рабочий стол\Работа с ИБД\ИД отряда (Ю) от 25.05.25.xlsx'!Таблица3[Столбец1]
Name Самоходная_артиллерия: #REF!
Name Системы_залпового_огня: #REF!
Name Системы_ПВО: #REF!
Name Системы_связи: #REF!
Name Танк: #REF!
Name Танки: #REF!
Name уточнение: #REF!
Name характер: 'C:\Users\rvolo\OneDrive\Рабочий стол\Работа с ИБД\ИД отряда (Ю) от 25.05.25.xlsx'!Таблица4[Столбец1]
Name цель: 'C:\Users\rvolo\OneDrive\Рабочий стол\Работа с ИБД\ИД отряда (Ю) от 25.05.25.xlsx'!Таблица5[Столбец1]
Name Автомобильная_техника: 'Справочная информация'!#REF!
Name Боевые_машины: 'Справочная информация'!#REF!
Name бп: 'C:\Users\Ноктбук №3\Desktop\образцы по отрядно\ИД отряда (Ц) от 00.00.25.xlsx'!Таблица9[Столбец1]
Name БПЛА: 'Справочная информация'!#REF!
Name Бронеавтомобили_и_MRAP: 'Справочная информация'!#REF!
Name Буксируемая_артиллерия: 'Справочная информация'!#REF!
Name дроны: 'C:\Users\Ноктбук №3\Desktop\образцы по отрядно\ИД отряда (Ц) от 00.00.25.xlsx'!Таблица2[Столбец1]
Name Инженерная_техника: 'Справочная информация'!#REF!
Name Инженерные_сооружения: 'Справочная информация'!#REF!
Name Личный_состав: 'Справочная информация'!#REF!
Name Надводные_суда: 'Справочная информация'!#REF!
Name Переносные_ударные_системы: 'Справочная информация'!#REF!

Sheet главная
A1: Итоговое донесение
A2: о результатах огневого поражения противника
A3: на Красноармейском тактическом направлении отряда
A4: "Рубикон-8" в период с 08:00 | E4: 03.09 | F4: по 08.00 | G4: 04.09.2025г.
B5: 1.Расчеты, задействованные в боевой работе:
B6: FPV К.Т. - | D6: 14 расчетов | F6: Zala- | H6: 2 расчета
B7: FPV С.Т. - | D7: 6 расчетов | F7: Lancet- | H7: 2 расчета
B8: Supercam- | D8: 2 расчета | F8: Черный глаз- | H8: 4 расчета
B9: Скальпель- | D9: 0 расчетов | F9: ПВО БЯ | H9: 2 расчета
B10: Орлан-10 | D10: 0 расчетов
B11: 2. Результаты боевого применения:
E12: FPV К.Т. | G12: FPV C.Т. | I12: Итого
A13: танк | E13: {=SUMPRODUCT(('8 (Отряд)'!$C$1:$C$1812="танк")*((ISNUMBER(SEARCH("КВН",'8 (Отряд)'!$H$1:$H$1812))+ISNUMBER(SEARCH("КВН-Т",'8 (Отряд)'!$H$1:$H$1812))+ISNUMBER(SEARCH("ПВХ-1",'8 (Отряд)'!$H$1:$H$1812))+ISNUMBER(SEARCH("ПВХ-1Т",'8 (Отряд)'!$H$1:$H$1812))+ISNUMBER(SEARCH("ПВХ-3",'8 (Отряд)'!$H$1:$H$1812))+ISNUMBER(SEARCH("ПВХ-3Т",'8 (Отряд)'!$H$1:$H$1812))+ISNUMBER(SEARCH("Бумеранг-10 (День)",'8 (Отряд)'!$H$1:$H$1812))+ISNUMBER(SEARCH("Бумеранг-10 (Ночь)",'8 (Отряд)'!$H$1:$H$1812))+ISNUMBER(SEARCH("ПВХ-5",'8 (Отряд)'!$H$1:$H$1812))+ISNUMBER(SEARCH("ПВХ-5Т",'8 (Отряд)'!$H$1:$H$1812)))>0)*('8 (Отряд)'!$M$1:$M$1812="уничтожение")*('8 (Отряд)'!$N$1:$N$1812="уничтожено"))} -> 0 | G13: {=SUMPRODUCT(('8 (Отряд)'!C1:C1812="танк")*((ISNUMBER(SEARCH("Молния-2",'8 (Отряд)'!H1:H1812))+ISNUMBER(SEARCH("Молния-2ДТ",'8 (Отряд)'!H1:H1812))+ISNUMBER(SEARCH("Утка Д",'8 (Отряд)'!H1:H1812))+ISNUMBER(SEARCH("Утка Н",'8 (Отряд)'!H1:H1812))+ISNUMBER(SEARCH("Ш-10",'8 (Отряд)'!H1:H1812))+ISNUMBER(SEARCH("Х-51",'8 (Отряд)'!H1:H1812))+ISNUMBER(SEARCH("Х-52",'8 (Отряд)'!H1:H1812))+ISNUMBER(SEARCH("Скальпель",'8 (Отряд)'!H1:H1812)))>0)*('8 (Отряд)'!M1:M1812="уничтожение")*('8 (Отряд)'!N1:N1812="уничтожено"))} -> 0 | I13: =E13+G13 -> 0
A14: самоходное артиллерийское орудие | E14: {=SUMPRODUCT(('8 (Отряд)'!$C$1:$C$1812=A14)*((ISNUMBER(SEARCH("КВН",'8 (Отряд)'!$H$1:$H$1812))+ISNUMBER(SEARCH("КВН-Т",'8 (Отряд)'!$H$1:$H$1812))+ISNUMBER(SEARCH("ПВХ-1",'8 (Отряд)'!$H$1:$H$1812))+ISNUMBER(SEARCH("ПВХ-1Т",'8 (Отряд)'!$H$1:$H$1812))+ISNUMBER(SEARCH("ПВХ-3",'8 (Отряд)'!$H$1:$H$1812))+ISNUMBER(SEARCH("ПВХ-3Т",'8 (Отряд)'!$H$1:$H$1812))+ISNUMBER(SEARCH("Бумеранг-10 (День)",'8 (Отряд)'!$H$1:$H$1812))+ISNUMBER(SEARCH("Бумеранг-10 (Ночь)",'8 (Отряд)'!$H$1:$H$1812))+ISNUMBER(SEARCH("ПВХ-5",'8 (Отряд)'!$H$1:$H$1812))+ISNUMBER(SEARCH("ПВХ-5Т",'8 (Отряд)'!$H$1:$H$1812)))>0)*('8 (Отряд)'!$M$1:$M$1812="уничтожение")*('8 (Отряд)'!$N$1:$N$1812="уничтожено"))} -> 0 | G14: {=SUMPRODUCT(('8 (Отряд)'!C1:C1812="самоходное артиллерийское орудие")*((ISNUMBER(SEARCH("Молния-2",'8 (Отряд)'!H1:H1812))+ISNUMBER(SEARCH("Молния-2ДТ",'8 (Отряд)'!H1:H1812))+ISNUMBER(SEARCH("Утка Д",'8 (Отряд)'!H1:H1812))+ISNUMBER(SEARCH("Утка Н",'8 (Отряд)'!H1:H1812))+ISNUMBER(SEARCH("Ш-10",'8 (Отряд)'!H1:H1812))+ISNUMBER(SEARCH("Х-51",'8 (Отряд)'!H1:H1812))+ISNUMBER(SEARCH("Х-52",'8 (Отряд)'!H1:H1812))+ISNUMBER(SEARCH("Скальпель",'8 (Отряд)'!H1:H1812)))>0)*('8 (Отряд)'!M1:M1812="уничтожение")*('8 (Отряд)'!N1:N1812="уничтожено"))} -> 0 | I14: =G14+E14 -> 0
A15: буксируемое артиллерийское орудие | E15: {=SUMPRODUCT(('8 (Отряд)'!$C$1:$C$1812=A15)*((ISNUMBER(SEARCH("КВН",'8 (Отряд)'!$H$1:$H$1812))+ISNUMBER(SEARCH("КВН-Т",'8 (Отряд)'!$H$1:$H$1812))+ISNUMBER(SEARCH("ПВХ-1",'8 (Отряд)'!$H$1:$H$1812))+ISNUMBER(SEARCH("ПВХ-1Т",'8 (Отряд)'!$H$1:$H$1812))+ISNUMBER(SEARCH("ПВХ-3",'8 (Отряд)'!$H$1:$H$1812))+ISNUMBER(SEARCH("ПВХ-3Т",'8 (Отряд)'!$H$1:$H$1812))+ISNUMBER(SEARCH("Бумеранг-10 (День)",'8 (Отряд)'!$H$1:$H$1812))+ISNUMBER(SEARCH("Бумеранг-10 (Ночь)",'8 (Отряд)'!$H$1:$H$1812))+ISNUMBER(SEARCH("ПВХ-5",'8 (Отряд)'!$H$1:$H$1812))+ISNUMBER(SEARCH("ПВХ-5Т",'8 (Отряд)'!$H$1:$H$1812)))>0)*('8 (Отряд)'!$M$1:$M$1812="уничтожение")*('8 (Отряд)'!$N$1:$N$1812="уничтожено"))} -> 0 | G15: {=SUMPRODUCT(('8 (Отряд)'!C1:C1812="буксируемое артиллерийское орудие")*((ISNUMBER(SEARCH("Молния-2",'8 (Отряд)'!H1:H1812))+ISNUMBER(SEARCH("Молния-2ДТ",'8 (Отряд)'!H1:H1812))+ISNUMBER(SEARCH("Утка Д",'8 (Отряд)'!H1:H1812))+ISNUMBER(SEARCH("Утка Н",'8 (Отряд)'!H1:H1812))+ISNUMBER(SEARCH("Ш-10",'8 (Отряд)'!H1:H1812))+ISNUMBER(SEARCH("Х-51",'8 (Отряд)'!H1:H1812))+ISNUMBER(SEARCH("Х-52",'8 (Отряд)'!H1:H1812))+ISNUMBER(SEARCH("Скальпель",'8 (Отряд)'!H1:H1812)))>0)*('8 (Отряд)'!M1:M1812="уничтожение")*('8 (Отряд)'!N1:N1812="уничтожено"))} -> 0 | I15: =G15+E15 -> 0
A16: РСЗО | E16: {=SUMPRODUCT(('8 (Отряд)'!$C$1:$C$1812=A16)*((ISNUMBER(SEARCH("КВН",'8 (Отряд)'!$H$1:$H$1812))+ISNUMBER(SEARCH("КВН-Т",'8 (Отряд)'!$H$1:$H$1812))+ISNUMBER(SEARCH("ПВХ-1",'8 (Отряд)'!$H$1:$H$1812))+ISNUMBER(SEARCH("ПВХ-1Т",'8 (Отряд)'!$H$1:$H$1812))+ISNUMBER(SEARCH("ПВХ-3",'8 (Отряд)'!$H$1:$H$1812))+ISNUMBER(SEARCH("ПВХ-3Т",'8 (Отряд)'!$H$1:$H$1812))+ISNUMBER(SEARCH("Бумеранг-10 (День)",'8 (Отряд)'!$H$1:$H$1812))+ISNUMBER(SEARCH("Бумеранг-10 (Ночь)",'8 (Отряд)'!$H$1:$H$1812))+ISNUMBER(SEARCH("ПВХ-5",'8 (Отряд)'!$H$1:$H$1812))+ISNUMBER(SEARCH("ПВХ-5Т",'8 (Отряд)'!$H$1:$H$1812)))>0)*('8 (Отряд)'!$M$1:$M$1812="уничтожение")*('8 (Отряд)'!$N$1:$N$1812="уничтожено"))} -> 0 | G16: {=SUMPRODUCT(('8 (Отряд)'!C1:C1812="РСЗО")*((ISNUMBER(SEARCH("Молния-2",'8 (Отряд)'!H1:H1812))+ISNUMBER(SEARCH("Молния-2ДТ",'8 (Отряд)'!H1:H1812))+ISNUMBER(SEARCH("Утка Д",'8 (Отряд)'!H1:H1812))+ISNUMBER(SEARCH("Утка Н",'8 (Отряд)'!H1:H1812))+ISNUMBER(SEARCH("Ш-10",'8 (Отряд)'!H1:H1812))+ISNUMBER(SEARCH("Х-51",'8 (Отряд)'!H1:H1812))+ISNUMBER(SEARCH("Х-52",'8 (Отряд)'!H1:H1812))+ISNUMBER(SEARCH("Скальпель",'8 (Отряд)'!H1:H1812)))>0)*('8 (Отряд)'!M1:M1812="уничтожение")*('8 (Отряд)'!N1:N1812="уничтожено"))} -> 0 | I16: =G16+E16 -> 0
A17: миномет | E17: {=SUMPRODUCT(('8 (Отряд)'!$C$1:$C$1812=A17)*((ISNUMBER(SEARCH("КВН",'8 (Отряд)'!$H$1:$H$1812))+ISNUMBER(SEARCH("КВН-Т",'8 (Отряд)'!$H$1:$H$1812))+ISNUMBER(SEARCH("ПВХ-1",'8 (Отряд)'!$H$1:$H$1812))+ISNUMBER(SEARCH("ПВХ-1Т",'8 (Отряд)'!$H$1:$H$1812))+ISNUMBER(SEARCH("ПВХ-3",'8 (Отряд)'!$H$1:$H$1812))+ISNUMBER(SEARCH("ПВХ-3Т",'8 (Отряд)'!$H$1:$H$1812))+ISNUMBER(SEARCH("Бумеранг-10 (День)",'8 (Отряд)'!$H$1:$H$1812))+ISNUMBER(SEARCH("Бумеранг-10 (Ночь)",'8 (Отряд)'!$H$1:$H$1812))+ISNUMBER(SEARCH("ПВХ-5",'8 (Отряд)'!$H$1:$H$1812))+ISNUMBER(SEARCH("ПВХ-5Т",'8 (Отряд)'!$H$1:$H$1812)))>0)*('8 (Отряд)'!$M$1:$M$1812="уничтожение")*('8 (Отряд)'!$N$1:$N$1812="уничтожено"))} -> 0 | G17: {=SUMPRODUCT(('8 (Отряд)'!C1:C1812="миномет")*((ISNUMBER(SEARCH("Молния-2",'8 (Отряд)'!H1:H1812))+ISNUMBER(SEARCH("Молния-2ДТ",'8 (Отряд)'!H1:H1812))+ISNUMBER(SEARCH("Утка Д",'8 (Отряд)'!H1:H1812))+ISNUMBER(SEARCH("Утка Н",'8 (Отряд)'!H1:H1812))+ISNUMBER(SEARCH("Ш-10",'8 (Отряд)'!H1:H1812))+ISNUMBER(SEARCH("Х-51",'8 (Отряд)'!H1:H1812))+ISNUMBER(SEARCH("Х-52",'8 (Отряд)'!H1:H1812))+ISNUMBER(SEARCH("Скальпель",'8 (Отряд)'!H1:H1812)))>0)*('8 (Отряд)'!M1:M1812="уничтожение")*('8 (Отряд)'!N1:N1812="уничтожено"))} -> 0 | I17: =G17+E17 -> 0
A18: ПТРК | E18: {=SUMPRODUCT(('8 (Отряд)'!$C$1:$C$1812=A18)*((ISNUMBER(SEARCH("КВН",'8 (Отряд)'!$H$1:$H$1812))+ISNUMBER(SEARCH("КВН-Т",'8 (Отряд)'!$H$1:$H$1812))+ISNUMBER(SEARCH("ПВХ-1",'8 (Отряд)'!$H$1:$H$1812))+ISNUMBER(SEARCH("ПВХ-1Т",'8 (Отряд)'!$H$1:$H$1812))+ISNUMBER(SEARCH("ПВХ-3",'8 (Отряд)'!$H$1:$H$1812))+ISNUMBER(SEARCH("ПВХ-3Т",'8 (Отряд)'!$H$1:$H$1812))+ISNUMBER(SEARCH("Бумеранг-10 (День)",'8 (Отряд)'!$H$1:$H$1812))+ISNUMBER(SEARCH("Бумеранг-10 (Ночь)",'8 (Отряд)'!$H$1:$H$1812))+ISNUMBER(SEARCH("ПВХ-5",'8 (Отряд)'!$H$1:$H$1812))+ISNUMBER(SEARCH("ПВХ-5Т",'8 (Отряд)'!$H$1:$H$1812)))>0)*('8 (Отряд)'!$M$1:$M$1812="уничтожение")*('8 (Отряд)'!$N$1:$N$1812="уничтожено"))} -> 0 | G18: {=SUMPRODUCT(('8 (Отряд)'!C1:C1812="ПТРК")*((ISNUMBER(SEARCH("Молния-2",'8 (Отряд)'!H1:H1812))+ISNUMBER(SEARCH("Молния-2ДТ",'8 (Отряд)'!H1:H1812))+ISNUMBER(SEARCH("Утка Д",'8 (Отряд)'!H1:H1812))+ISNUMBER(SEARCH("Утка Н",'8 (Отряд)'!H1:H1812))+ISNUMBER(SEARCH("Ш-10",'8 (Отряд)'!H1:H1812))+ISNUMBER(SEARCH("Х-51",'8 (Отряд)'!H1:H1812))+ISNUMBER(SEARCH("Х-52",'8 (Отряд)'!H1:H1812))+ISNUMBER(SEARCH("Скальпель",'8 (Отряд)'!H1:H1812)))>0)*('8 (Отряд)'!M1:M1812="уничтожение")*('8 (Отряд)'!N1:N1812="уничтожено"))} -> 0 | I18: =G18+E18 -> 0
A19: зенитная установка | E19: {=SUMPRODUCT(('8 (Отряд)'!$C$1:$C$1812=A19)*((ISNUMBER(SEARCH("КВН",'8 (Отряд)'!$H$1:$H$1812))+ISNUMBER(SEARCH("КВН-Т",'8 (Отряд)'!$H$1:$H$1812))+ISNUMBER(SEARCH("ПВХ-1",'8 (Отряд)'!$H$1:$H$1812))+ISNUMBER(SEARCH("ПВХ-1Т",'8 (Отряд)'!$H$1:$H$1812))+ISNUMBER(SEARCH("ПВХ-3",'8 (Отряд)'!$H$1:$H$1812))+ISNUMBER(SEARCH("ПВХ-3Т",'8 (Отряд)'!$H$1:$H$1812))+ISNUMBER(SEARCH("Бумеранг-10 (День)",'8 (Отряд)'!$H$1:$H$1812))+ISNUMBER(SEARCH("Бумеранг-10 (Ночь)",'8 (Отряд)'!$H$1:$H$1812))+ISNUMBER(SEARCH("ПВХ-5",'8 (Отряд)'!$H$1:$H$1812))+ISNUMBER(SEARCH("ПВХ-5Т",'8 (Отряд)'!$H$1:$H$1812)))>0)*('8 (Отряд)'!$M$1:$M$1812="уничтожение")*('8 (Отряд)'!$N$1:$N$1812="уничтожено"))} -> 0 | G19: {=SUMPRODUCT(('8 (Отряд)'!C1:C1812="зенитная установка")*((ISNUMBER(SEARCH("Молния-2",'8 (Отряд)'!H1:H1812))+ISNUMBER(SEARCH("Молния-2ДТ",'8 (Отряд)'!H1:H1812))+ISNUMBER(SEARCH("Утка Д",'8 (Отряд)'!H1:H1812))+ISNUMBER(SEARCH("Утка Н",'8 (Отряд)'!H1:H1812))+ISNUMBER(SEARCH("Ш-10",'8 (Отряд)'!H1:H1812))+ISNUMBER(SEARCH("Х-51",'8 (Отряд)'!H1:H1812))+ISNUMBER(SEARCH("Х-52",'8 (Отряд)'!H1:H1812))+ISNUMBER(SEARCH("Скальпель",'8 (Отряд)'!H1:H1812)))>0)*('8 (Отряд)'!M1:M1812="уничтожение")*('8 (Отряд)'!N1:N1812="уничтожено"))} -> 0 | I19: =G19+E19 -> 0
A20: боевая машина пехоты | E20: {=SUMPRODUCT(('8 (Отряд)'!$C$1:$C$1812=A20)*((ISNUMBER(SEARCH("КВН",'8 (Отряд)'!$H$1:$H$1812))+ISNUMBER(SEARCH("КВН-Т",'8 (Отряд)'!$H$1:$H$1812))+ISNUMBER(SEARCH("ПВХ-1",'8 (Отряд)'!$H$1:$H$1812))+ISNUMBER(SEARCH("ПВХ-1Т",'8 (Отряд)'!$H$1:$H$1812))+ISNUMBER(SEARCH("ПВХ-3",'8 (Отряд)'!$H$1:$H$1812))+ISNUMBER(SEARCH("ПВХ-3Т",'8 (Отряд)'!$H$1:$H$1812))+ISNUMBER(SEARCH("Бумеранг-10 (День)",'8 (Отряд)'!$H$1:$H$1812))+ISNUMBER(SEARCH("Бумеранг-10 (Ночь)",'8 (Отряд)'!$H$1:$H$1812))+ISNUMBER(SEARCH("ПВХ-5",'8 (Отряд)'!$H$1:$H$1812))+ISNUMBER(SEARCH("ПВХ-5Т",'8 (Отряд)'!$H$1:$H$1812)))>0)*('8 (Отряд)'!$M$1:$M$1812="уничтожение")*('8 (Отряд)'!$N$1:$N$1812="уничтожено"))} -> 0 | G20: {=SUMPRODUCT(('8 (Отряд)'!C1:C1812="боевая машина пехоты")*((ISNUMBER(SEARCH("Молния-2",'8 (Отряд)'!H1:H1812))+ISNUMBER(SEARCH("Молния-2ДТ",'8 (Отряд)'!H1:H1812))+ISNUMBER(SEARCH("Утка Д",'8 (Отряд)'!H1:H1812))+ISNUMBER(SEARCH("Утка Н",'8 (Отряд)'!H1:H1812))+ISNUMBER(SEARCH("Ш-10",'8 (Отряд)'!H1:H1812))+ISNUMBER(SEARCH("Х-51",'8 (Отряд)'!H1:H1812))+ISNUMBER(SEARCH("Х-52",'8 (Отряд)'!H1:H1812))+ISNUMBER(SEARCH("Скальпель",'8 (Отряд)'!H1:H1812)))>0)*('8 (Отряд)'!M1:M1812="уничтожение")*('8 (Отряд)'!N1:N1812="уничтожено"))} -> 0 | I20: =G20+E20 -> 0
A21: бронетранспортер | E21: {=SUMPRODUCT(('8 (Отряд)'!$C$1:$C$1812=A21)*((ISNUMBER(SEARCH("КВН",'8 (Отряд)'!$H$1:$H$1812))+ISNUMBER(SEARCH("КВН-Т",'8 (Отряд)'!$H$1:$H$1812))+ISNUMBER(SEARCH("ПВХ-1",'8 (Отряд)'!$H$1:$H$1812))+ISNUMBER(SEARCH("ПВХ-1Т",'8 (Отряд)'!$H$1:$H$1812))+ISNUMBER(SEARCH("ПВХ-3",'8 (Отряд)'!$H$1:$H$1812))+ISNUMBER(SEARCH("ПВХ-3Т",'8 (Отряд)'!$H$1:$H$1812))+ISNUMBER(SEARCH("Бумеранг-10 (День)",'8 (Отряд)'!$H$1:$H$1812))+ISNUMBER(SEARCH("Бумеранг-10 (Ночь)",'8 (Отряд)'!$H$1:$H$1812))+ISNUMBER(SEARCH("ПВХ-5",'8 (Отряд)'!$H$1:$H$1812))+ISNUMBER(SEARCH("ПВХ-5Т",'8 (Отряд)'!$H$1:$H$1812)))>0)*('8 (Отряд)'!$M$1:$M$1812="уничтожение")*('8 (Отряд)'!$N$1:$N$1812="уничтожено"))} -> 0 | G21: {=SUMPRODUCT(('8 (Отряд)'!C1:C1812="бронетранспортер")*((ISNUMBER(SEARCH("Молния-2",'8 (Отряд)'!H1:H1812))+ISNUMBER(SEARCH("Молния-2ДТ",'8 (Отряд)'!H1:H1812))+ISNUMBER(SEARCH("Утка Д",'8 (Отряд)'!H1:H1812))+ISNUMBER(SEARCH("Утка Н",'8 (Отряд)'!H1:H1812))+ISNUMBER(SEARCH("Ш-10",'8 (Отряд)'!H1:H1812))+ISNUMBER(SEARCH("Х-51",'8 (Отряд)'!H1:H1812))+ISNUMBER(SEARCH("Х-52",'8 (Отряд)'!H1:H1812))+ISNUMBER(SEARCH("Скальпель",'8 (Отряд)'!H1:H1812)))>0)*('8 (Отряд)'!M1:M1812="уничтожение")*('8 (Отряд)'!N1:N1812="уничтожено"))} -> 0 | I21: =G21+E21 -> 0
A22: боевая бронированная машина | E22: {=SUMPRODUCT(('8 (Отряд)'!$C$1:$C$1812=A22)*((ISNUMBER(SEARCH("КВН",'8 (Отряд)'!$H$1:$H$1812))+ISNUMBER(SEARCH("КВН-Т",'8 (Отряд)'!$H$1:$H$1812))+ISNUMBER(SEARCH("ПВХ-1",'8 (Отряд)'!$H$1:$H$1812))+ISNUMBER(SEARCH("ПВХ-1Т",'8 (Отряд)'!$H$1:$H$1812))+ISNUMBER(SEARCH("ПВХ-3",'8 (Отряд)'!$H$1:$H$1812))+ISNUMBER(SEARCH("ПВХ-3Т",'8 (Отряд)'!$H$1:$H$1812))+ISNUMBER(SEARCH("Бумеранг-10 (День)",'8 (Отряд)'!$H$1:$H$1812))+ISNUMBER(SEARCH("Бумеранг-10 (Ночь)",'8 (Отряд)'!$H$1:$H$1812))+ISNUMBER(SEARCH("ПВХ-5",'8 (Отряд)'!$H$1:$H$1812))+ISNUMBER(SEARCH("ПВХ-5Т",'8 (Отряд)'!$H$1:$H$1812)))>0)*('8 (Отряд)'!$M$1:$M$1812="уничтожение")*('8 (Отряд)'!$N$1:$N$1812="уничтожено"))} -> 0 | G22: {=SUMPRODUCT(('8 (Отряд)'!C1:C1812="боевая бронированная машина")*((ISNUMBER(SEARCH("Молния-2",'8 (Отряд)'!H1:H1812))+ISNUMBER(SEARCH("Молния-2ДТ",'8 (Отряд)'!H1:H1812))+ISNUMBER(SEARCH("Утка Д",'8 (Отряд)'!H1:H1812))+ISNUMBER(SEARCH("Утка Н",'8 (Отряд)'!H1:H1812))+ISNUMBER(SEARCH("Ш-10",'8 (Отряд)'!H1:H1812))+ISNUMBER(SEARCH("Х-51",'8 (Отряд)'!H1:H1812))+ISNUMBER(SEARCH("Х-52",'8 (Отряд)'!H1:H1812))+ISNUMBER(SEARCH("Скальпель",'8 (Отряд)'!H1:H1812)))>0)*('8 (Отряд)'!M1:M1812="уничтожение")*('8 (Отряд)'!N1:N1812="уничтожено"))} -> 0 | I22: =G22+E22 -> 0
A23: РЛС | E23: {=SUMPRODUCT(('8 (Отряд)'!$C$1:$C$1812=A23)*((ISNUMBER(SEARCH("КВН",'8 (Отряд)'!$H$1:$H$1812))+ISNUMBER(SEARCH("КВН-Т",'8 (Отряд)'!$H$1:$H$1812))+ISNUMBER(SEARCH("ПВХ-1",'8 (Отряд)'!$H$1:$H$1812))+ISNUMBER(SEARCH("ПВХ-1Т",'8 (Отряд)'!$H$1:$H$1812))+ISNUMBER(SEARCH("ПВХ-3",'8 (Отряд)'!$H$1:$H$1812))+ISNUMBER(SEARCH("ПВХ-3Т",'8 (Отряд)'!$H$1:$H$1812))+ISNUMBER(SEARCH("Бумеранг-10 (День)",'8 (Отряд)'!$H$1:$H$1812))+ISNUMBER(SEARCH("Бумеранг-10 (Ночь)",'8 (Отряд)'!$H$1:$H$1812))+ISNUMBER(SEARCH("ПВХ-5",'8 (Отряд)'!$H$1:$H$1812))+ISNUMBER(SEARCH("ПВХ-5Т",'8 (Отряд)'!$H$1:$H$1812)))>0)*('8 (Отряд)'!$M$1:$M$1812="уничтожение")*('8 (Отряд)'!$N$1:$N$1812="уничтожено"))} -> 0 | G23: {=SUMPRODUCT(('8 (Отряд)'!C1:C1812="РЛС")*((ISNUMBER(SEARCH("Молния-2",'8 (Отряд)'!H1:H1812))+ISNUMBER(SEARCH("Молния-2ДТ",'8 (Отряд)'!H1:H1812))+ISNUMBER(SEARCH("Утка Д",'8 (Отряд)'!H1:H1812))+ISNUMBER(SEARCH("Утка Н",'8 (Отряд)'!H1:H1812))+ISNUMBER(SEARCH("Ш-10",'8 (Отряд)'!H1:H1812))+ISNUMBER(SEARCH("Х-51",'8 (Отряд)'!H1:H1812))+ISNUMBER(SEARCH("Х-52",'8 (Отряд)'!H1:H1812))+ISNUMBER(SEARCH("Скальпель",'8 (Отряд)'!H1:H1812)))>0)*('8 (Отряд)'!M1:M1812="уничтожение")*('8 (Отряд)'!N1:N1812="уничтожено"))} -> 0 | I23: =G23+E23 -> 0
A24: РЭР | E24: {=SUMPRODUCT(('8 (Отряд)'!$C$1:$C$1812=A24)*((ISNUMBER(SEARCH("КВН",'8 (Отряд)'!$H$1:$H$1812))+ISNUMBER(SEARCH("КВН-Т",'8 (Отряд)'!$H$1:$H$1812))+ISNUMBER(SEARCH("ПВХ-1",'8 (Отряд)'!$H$1:$H$1812))+ISNUMBER(SEARCH("ПВХ-1Т",'8 (Отряд)'!$H$1:$H$1812))+ISNUMBER(SEARCH("ПВХ-3",'8 (Отряд)'!$H$1:$H$1812))+ISNUMBER(SEARCH("ПВХ-3Т",'8 (Отряд)'!$H$1:$H$1812))+ISNUMBER(SEARCH("Бумеранг-10 (День)",'8 (Отряд)'!$H$1:$H$1812))+ISNUMBER(SEARCH("Бумеранг-10 (Ночь)",'8 (Отряд)'!$H$1:$H$1812))+ISNUMBER(SEARCH("ПВХ-5",'8 (Отряд)'!$H$1:$H$1812))+ISNUMBER(SEARCH("ПВХ-5Т",'8 (Отряд)'!$H$1:$H$1812)))>0)*('8 (Отряд)'!$M$1:$M$1812="уничтожение")*('8 (Отряд)'!$N$1:$N$1812="уничтожено"))} -> 0 | G24: {=SUMPRODUCT(('8 (Отряд)'!C1:C1812="РЭР")*((ISNUMBER(SEARCH("Молния-2",'8 (Отряд)'!H1:H1812))+ISNUMBER(SEARCH("Молния-2ДТ",'8 (Отряд)'!H1:H1812))+ISNUMBER(SEARCH("Утка Д",'8 (Отряд)'!H1:H1812))+ISNUMBER(SEARCH("Утка Н",'8 (Отряд)'!H1:H1812))+ISNUMBER(SEARCH("Ш-10",'8 (Отряд)'!H1:H1812))+ISNUMBER(SEARCH("Х-51",'8 (Отряд)'!H1:H1812))+ISNUMBER(SEARCH("Х-52",'8 (Отряд)'!H1:H1812))+ISNUMBER(SEARCH("Скальпель",'8 (Отряд)'!H1:H1812)))>0)*('8 (Отряд)'!M1:M1812="уничтожение")*('8 (Отряд)'!N1:N1812="уничтожено"))} -> 0 | I24: =G24+E24 -> 0
A25: РЭБ | E25: {=SUMPRODUCT(('8 (Отряд)'!$C$1:$C$1812=A25)*((ISNUMBER(SEARCH("КВН",'8 (Отряд)'!$H$1:$H$1812))+ISNUMBER(SEARCH("КВН-Т",'8 (Отряд)'!$H$1:$H$1812))+ISNUMBER(SEARCH("ПВХ-1",'8 (Отряд)'!$H$1:$H$1812))+ISNUMBER(SEARCH("ПВХ-1Т",'8 (Отряд)'!$H$1:$H$1812))+ISNUMBER(SEARCH("ПВХ-3",'8 (Отряд)'!$H$1:$H$1812))+ISNUMBER(SEARCH("ПВХ-3Т",'8 (Отряд)'!$H$1:$H$1812))+ISNUMBER(SEARCH("Бумеранг-10 (День)",'8 (Отряд)'!$H$1:$H$1812))+ISNUMBER(SEARCH("Бумеранг-10 (Ночь)",'8 (Отряд)'!$H$1:$H$1812))+ISNUMBER(SEARCH("ПВХ-5",'8 (Отряд)'!$H$1:$H$1812))+ISNUMBER(SEARCH("ПВХ-5Т",'8 (Отряд)'!$H$1:$H$1812)))>0)*('8 (Отряд)'!$M$1:$M$1812="уничтожение")*('8 (Отряд)'!$N$1:$N$1812="уничтожено"))} -> 0 | G25: {=SUMPRODUCT(('8 (Отряд)'!C1:C1812="РЭБ")*((ISNUMBER(SEARCH("Молния-2",'8 (Отряд)'!H1:H1812))+ISNUMBER(SEARCH("Молния-2ДТ",'8 (Отряд)'!H1:H1812))+ISNUMBER(SEARCH("Утка Д",'8 (Отряд)'!H1:H1812))+ISNUMBER(SEARCH("Утка Н",'8 (Отряд)'!H1:H1812))+ISNUMBER(SEARCH("Ш-10",'8 (Отряд)'!H1:H1812))+ISNUMBER(SEARCH("Х-51",'8 (Отряд)'!H1:H1812))+ISNUMBER(SEARCH("Х-52",'8 (Отряд)'!H1:H1812))+ISNUMBER(SEARCH("Скальпель",'8 (Отряд)'!H1:H1812)))>0)*('8 (Отряд)'!M1:M1812="уничтожение")*('8 (Отряд)'!N1:N1812="уничтожено"))} -> 0 | I25: =G25+E25 -> 0
A26: автомобильная техника | E26: {=SUMPRODUCT(('8 (Отряд)'!$C$1:$C$1812=A26)*((ISNUMBER(SEARCH("КВН",'8 (Отряд)'!$H$1:$H$1812))+ISNUMBER(SEARCH("КВН-Т",'8 (Отряд)'!$H$1:$H$1812))+ISNUMBER(SEARCH("ПВХ-1",'8 (Отряд)'!$H$1:$H$1812))+ISNUMBER(SEARCH("ПВХ-1Т",'8 (Отряд)'!$H$1:$H$1812))+ISNUMBER(SEARCH("ПВХ-3",'8 (Отряд)'!$H$1:$H$1812))+ISNUMBER(SEARCH("ПВХ-3Т",'8 (Отряд)'!$H$1:$H$1812))+ISNUMBER(SEARCH("Бумеранг-10 (День)",'8 (Отряд)'!$H$1:$H$1812))+ISNUMBER(SEARCH("Бумеранг-10 (Ночь)",'8 (Отряд)'!$H$1:$H$1812))+ISNUMBER(SEARCH("ПВХ-5",'8 (Отряд)'!$H$1:$H$1812))+ISNUMBER(SEARCH("ПВХ-5Т",'8 (Отряд)'!$H$1:$H$1812)))>0)*('8 (Отряд)'!$M$1:$M$1812="уничтожение")*('8 (Отряд)'!$N$1:$N$1812="уничтожено"))} -> 0 | G26: {=SUMPRODUCT(('8 (Отряд)'!C1:C1812="автомобильная техника")*((ISNUMBER(SEARCH("Молния-2",'8 (Отряд)'!H1:H1812))+ISNUMBER(SEARCH("Молния-2ДТ",'8 (Отряд)'!H1:H1812))+ISNUMBER(SEARCH("Утка Д",'8 (Отряд)'!H1:H1812))+ISNUMBER(SEARCH("Утка Н",'8 (Отряд)'!H1:H1812))+ISNUMBER(SEARCH("Ш-10",'8 (Отряд)'!H1:H1812))+ISNUMBER(SEARCH("Х-51",'8 (Отряд)'!H1:H1812))+ISNUMBER(SEARCH("Х-52",'8 (Отряд)'!H1:H1812))+ISNUMBER(SEARCH("Скальпель",'8 (Отряд)'!H1:H1812)))>0)*('8 (Отряд)'!M1:M1812="уничтожение")*('8 (Отряд)'!N1:N1812="уничтожено"))} -> 0 | I26: =G26+E26 -> 0
A27: мототехника | E27: {=SUMPRODUCT(('8 (Отряд)'!$C$1:$C$1812=A27)*((ISNUMBER(SEARCH("КВН",'8 (Отряд)'!$H$1:$H$1812))+ISNUMBER(SEARCH("КВН-Т",'8 (Отряд)'!$H$1:$H$1812))+ISNUMBER(SEARCH("ПВХ-1",'8 (Отряд)'!$H$1:$H$1812))+ISNUMBER(SEARCH("ПВХ-1Т",'8 (Отряд)'!$H$1:$H$1812))+ISNUMBER(SEARCH("ПВХ-3",'8 (Отряд)'!$H$1:$H$1812))+ISNUMBER(SEARCH("ПВХ-3Т",'8 (Отряд)'!$H$1:$H$1812))+ISNUMBER(SEARCH("Бумеранг-10 (День)",'8 (Отряд)'!$H$1:$H$1812))+ISNUMBER(SEARCH("Бумеранг-10 (Ночь)",'8 (Отряд)'!$H$1:$H$1812))+ISNUMBER(SEARCH("ПВХ-5",'8 (Отряд)'!$H$1:$H$1812))+ISNUMBER(SEARCH("ПВХ-5Т",'8 (Отряд)'!$H$1:$H$1812)))>0)*('8 (Отряд)'!$M$1:$M$1812="уничтожение")*('8 (Отряд)'!$N$1:$N$1812="уничтожено"))} -> 0 | G27: {=SUMPRODUCT(('8 (Отряд)'!C1:C1812="мототехника")*((ISNUMBER(SEARCH("Молния-2",'8 (Отряд)'!H1:H1812))+ISNUMBER(SEARCH("Молния-2ДТ",'8 (Отряд)'!H1:H1812))+ISNUMBER(SEARCH("Утка Д",'8 (Отряд)'!H1:H1812))+ISNUMBER(SEARCH("Утка Н",'8 (Отряд)'!H1:H1812))+ISNUMBER(SEARCH("Ш-10",'8 (Отряд)'!H1:H1812))+ISNUMBER(SEARCH("Х-51",'8 (Отряд)'!H1:H1812))+ISNUMBER(SEARCH("Х-52",'8 (Отряд)'!H1:H1812))+ISNUMBER(SEARCH("Скальпель",'8 (Отряд)'!H1:H1812)))>0)*('8 (Отряд)'!M1:M1812="уничтожение")*('8 (Отряд)'!N1:N1812="уничтожено"))} -> 0 | I27: =G27+E27 -> 0
A28: инженерная техника | E28: {=SUMPRODUCT(('8 (Отряд)'!$C$1:$C$1812=A28)*((ISNUMBER(SEARCH("КВН",'8 (Отряд)'!$H$1:$H$1812))+ISNUMBER(SEARCH("КВН-Т",'8 (Отряд)'!$H$1:$H$1812))+ISNUMBER(SEARCH("ПВХ-1",'8 (Отряд)'!$H$1:$H$1812))+ISNUMBER(SEARCH("ПВХ-1Т",'8 (Отряд)'!$H$1:$H$1812))+ISNUMBER(SEARCH("ПВХ-3",'8 (Отряд)'!$H$1:$H$1812))+ISNUMBER(SEARCH("ПВХ-3Т",'8 (Отряд)'!$H$1:$H$1812))+ISNUMBER(SEARCH("Бумеранг-10 (День)",'8 (Отряд)'!$H$1:$H$1812))+ISNUMBER(SEARCH("Бумеранг-10 (Ночь)",'8 (Отряд)'!$H$1:$H$1812))+ISNUMBER(SEARCH("ПВХ-5",'8 (Отряд)'!$H$1:$H$1812))+ISNUMBER(SEARCH("ПВХ-5Т",'8 (Отряд)'!$H$1:$H$1812)))>0)*('8 (Отряд)'!$M$1:$M$1812="уничтожение")*('8 (Отряд)'!$N$1:$N$1812="уничтожено"))} -> 0 | G28: {=SUMPRODUCT(('8 (Отряд)'!C1:C1812="инженерная техника")*((ISNUMBER(SEARCH("Молния-2",'8 (Отряд)'!H1:H1812))+ISNUMBER(SEARCH("Молния-2ДТ",'8 (Отряд)'!H1:H1812))+ISNUMBER(SEARCH("Утка Д",'8 (Отряд)'!H1:H1812))+ISNUMBER(SEARCH("Утка Н",'8 (Отряд)'!H1:H1812))+ISNUMBER(SEARCH("Ш-10",'8 (Отряд)'!H1:H1812))+ISNUMBER(SEARCH("Х-51",'8 (Отряд)'!H1:H1812))+ISNUMBER(SEARCH("Х-52",'8 (Отряд)'!H1:H1812))+ISNUMBER(SEARCH("Скальпель",'8 (Отряд)'!H1:H1812)))>0)*('8 (Отряд)'!M1:M1812="уничтожение")*('8 (Отряд)'!N1:N1812="уничтожено"))} -> 0 | I28: =G28+E28 -> 0
A29: ПУ БпЛА | E29: {=SUMPRODUCT(('8 (Отряд)'!$C$1:$C$1812=A29)*((ISNUMBER(SEARCH("КВН",'8 (Отряд)'!$H$1:$H$1812))+ISNUMBER(SEARCH("КВН-Т",'8 (Отряд)'!$H$1:$H$1812))+ISNUMBER(SEARCH("ПВХ-1",'8 (Отряд)'!$H$1:$H$1812))+ISNUMBER(SEARCH("ПВХ-1Т",'8 (Отряд)'!$H$1:$H$1812))+ISNUMBER(SEARCH("ПВХ-3",'8 (Отряд)'!$H$1:$H$1812))+ISNUMBER(SEARCH("ПВХ-3Т",'8 (Отряд)'!$H$1:$H$1812))+ISNUMBER(SEARCH("Бумеранг-10 (День)",'8 (Отряд)'!$H$1:$H$1812))+ISNUMBER(SEARCH("Бумеранг-10 (Ночь)",'8 (Отряд)'!$H$1:$H$1812))+ISNUMBER(SEARCH("ПВХ-5",'8 (Отряд)'!$H$1:$H$1812))+ISNUMBER(SEARCH("ПВХ-5Т",'8 (Отряд)'!$H$1:$H$1812)))>0)*('8 (Отряд)'!$M$1:$M$1812="уничтожение")*('8 (Отряд)'!$N$1:$N$1812="уничтожено"))} -> 0 | G29: {=SUMPRODUCT(('8 (Отряд)'!C1:C1812="ПУ БпЛА")*((ISNUMBER(SEARCH("Молния-2",'8 (Отряд)'!H1:H1812))+ISNUMBER(SEARCH("Молния-2ДТ",'8 (Отряд)'!H1:H1812))+ISNUMBER(SEARCH("Утка Д",'8 (Отряд)'!H1:H1812))+ISNUMBER(SEARCH("Утка Н",'8 (Отряд)'!H1:H1812))+ISNUMBER(SEARCH("Ш-10",'8 (Отряд)'!H1:H1812))+ISNUMBER(SEARCH("Х-51",'8 (Отряд)'!H1:H1812))+ISNUMBER(SEARCH("Х-52",'8 (Отряд)'!H1:H1812))+ISNUMBER(SEARCH("Скальпель",'8 (Отряд)'!H1:H1812)))>0)*('8 (Отряд)'!M1:M1812="уничтожение")*('8 (Отряд)'!N1:N1812="уничтожено"))} -> 0 | I29: =G29+E29 -> 0
A30: БпЛА | E30: {=SUMPRODUCT(('8 (Отряд)'!$C$1:$C$1812=A30)*((ISNUMBER(SEARCH("КВН",'8 (Отряд)'!$H$1:$H$1812))+ISNUMBER(SEARCH("КВН-Т",'8 (Отряд)'!$H$1:$H$1812))+ISNUMBER(SEARCH("ПВХ-1",'8 (Отряд)'!$H$1:$H$1812))+ISNUMBER(SEARCH("ПВХ-1Т",'8 (Отряд)'!$H$1:$H$1812))+ISNUMBER(SEARCH("ПВХ-3",'8 (Отряд)'!$H$1:$H$1812))+ISNUMBER(SEARCH("ПВХ-3Т",'8 (Отряд)'!$H$1:$H$1812))+ISNUMBER(SEARCH("Бумеранг-10 (День)",'8 (Отряд)'!$H$1:$H$1812))+ISNUMBER(SEARCH("Бумеранг-10 (Ночь)",'8 (Отряд)'!$H$1:$H$1812))+ISNUMBER(SEARCH("ПВХ-5",'8 (Отряд)'!$H$1:$H$1812))+ISNUMBER(SEARCH("ПВХ-5Т",'8 (Отряд)'!$H$1:$H$1812)))>0)*('8 (Отряд)'!$M$1:$M$1812="уничтожение")*('8 (Отряд)'!$N$1:$N$1812="уничтожено"))} -> 0 | G30: {=SUMPRODUCT(('8 (Отряд)'!C1:C1812="БпЛА")*((ISNUMBER(SEARCH("Молния-2",'8 (Отряд)'!H1:H1812))+ISNUMBER(SEARCH("Молния-2ДТ",'8 (Отряд)'!H1:H1812))+ISNUMBER(SEARCH("Утка Д",'8 (Отряд)'!H1:H1812))+ISNUMBER(SEARCH("Утка Н",'8 (Отряд)'!H1:H1812))+ISNUMBER(SEARCH("Ш-10",'8 (Отряд)'!H1:H1812))+ISNUMBER(SEARCH("Х-51",'8 (Отряд)'!H1:H1812))+ISNUMBER(SEARCH("Х-52",'8 (Отряд)'!H1:H1812))+ISNUMBER(SEARCH("Скальпель",'8 (Отряд)'!H1:H1812)))>0)*('8 (Отряд)'!M1:M1812="уничтожение")*('8 (Отряд)'!N1:N1812="уничтожено"))} -> 0 | I30: =G30+E30 -> 0
A31: Наземные дроны | E31: {=SUMPRODUCT(('8 (Отряд)'!$C$1:$C$1812=A31)*((ISNUMBER(SEARCH("КВН",'8 (Отряд)'!$H$1:$H$1812))+ISNUMBER(SEARCH("КВН-Т",'8 (Отряд)'!$H$1:$H$1812))+ISNUMBER(SEARCH("ПВХ-1",'8 (Отряд)'!$H$1:$H$1812))+ISNUMBER(SEARCH("ПВХ-1Т",'8 (Отряд)'!$H$1:$H$1812))+ISNUMBER(SEARCH("ПВХ-3",'8 (Отряд)'!$H$1:$H$1812))+ISNUMBER(SEARCH("ПВХ-3Т",'8 (Отряд)'!$H$1:$H$1812))+ISNUMBER(SEARCH("Бумеранг-10 (День)",'8 (Отряд)'!$H$1:$H$1812))+ISNUMBER(SEARCH("Бумеранг-10 (Ночь)",'8 (Отряд)'!$H$1:$H$1812))+ISNUMBER(SEARCH("ПВХ-5",'8 (Отряд)'!$H$1:$H$1812))+ISNUMBER(SEARCH("ПВХ-5Т",'8 (Отряд)'!$H$1:$H$1812)))>0)*('8 (Отряд)'!$M$1:$M$1812="уничтожение")*('8 (Отряд)'!$N$1:$N$1812="уничтожено"))} -> 0 | G31: {=SUMPRODUCT(('8 (Отряд)'!C1:C1812="наземные дроны")*((ISNUMBER(SEARCH("Молния-2",'8 (Отряд)'!H1:H1812))+ISNUMBER(SEARCH("Молния-2ДТ",'8 (Отряд)'!H1:H1812))+ISNUMBER(SEARCH("Утка Д",'8 (Отряд)'!H1:H1812))+ISNUMBER(SEARCH("Утка Н",'8 (Отряд)'!H1:H1812))+ISNUMBER(SEARCH("Ш-10",'8 (Отряд)'!H1:H1812))+ISNUMBER(SEARCH("Х-51",'8 (Отряд)'!H1:H1812))+ISNUMBER(SEARCH("Х-52",'8 (Отряд)'!H1:H1812))+ISNUMBER(SEARCH("Скальпель",'8 (Отряд)'!H1:H1812)))>0)*('8 (Отряд)'!M1:M1812="уничтожение")*('8 (Отряд)'!N1:N1812="уничтожено"))} -> 0 | I31: =G31+E31 -> 0
A32: Баба Яга | E32: {=SUMPRODUCT(('8 (Отряд)'!$C$1:$C$1812=A32)*((ISNUMBER(SEARCH("КВН",'8 (Отряд)'!$H$1:$H$1812))+ISNUMBER(SEARCH("КВН-Т",'8 (Отряд)'!$H$1:$H$1812))+ISNUMBER(SEARCH("ПВХ-1",'8 (Отряд)'!$H$1:$H$1812))+ISNUMBER(SEARCH("ПВХ-1Т",'8 (Отряд)'!$H$1:$H$1812))+ISNUMBER(SEARCH("ПВХ-3",'8 (Отряд)'!$H$1:$H$1812))+ISNUMBER(SEARCH("ПВХ-3Т",'8 (Отряд)'!$H$1:$H$1812))+ISNUMBER(SEARCH("Бумеранг-10 (День)",'8 (Отряд)'!$H$1:$H$1812))+ISNUMBER(SEARCH("Бумеранг-10 (Ночь)",'8 (Отряд)'!$H$1:$H$1812))+ISNUMBER(SEARCH("ПВХ-5",'8 (Отряд)'!$H$1:$H$1812))+ISNUMBER(SEARCH("ПВХ-5Т",'8 (Отряд)'!$H$1:$H$1812)))>0)*('8 (Отряд)'!$M$1:$M$1812="уничтожение")*('8 (Отряд)'!$N$1:$N$1812="уничтожено"))} -> 0 | G32: {=SUMPRODUCT(('8 (Отряд)'!C1:C1812="Баба Яга")*((ISNUMBER(SEARCH("Молния-2",'8 (Отряд)'!H1:H1812))+ISNUMBER(SEARCH("Молния-2ДТ",'8 (Отряд)'!H1:H1812))+ISNUMBER(SEARCH("Утка Д",'8 (Отряд)'!H1:H1812))+ISNUMBER(SEARCH("Утка Н",'8 (Отряд)'!H1:H1812))+ISNUMBER(SEARCH("Ш-10",'8 (Отряд)'!H1:H1812))+ISNUMBER(SEARCH("Х-51",'8 (Отряд)'!H1:H1812))+ISNUMBER(SEARCH("Х-52",'8 (Отряд)'!H1:H1812))+ISNUMBER(SEARCH("Скальпель",'8 (Отряд)'!H1:H1812)))>0)*('8 (Отряд)'!M1:M1812="уничтожение")*('8 (Отряд)'!N1:N1812="уничтожено"))} -> 0 | I32: =G32+E32 -> 0
A33: пункт управления | E33: {=SUMPRODUCT(('8 (Отряд)'!$C$1:$C$1812=A33)*((ISNUMBER(SEARCH("КВН",'8 (Отряд)'!$H$1:$H$1812))+ISNUMBER(SEARCH("КВН-Т",'8 (Отряд)'!$H$1:$H$1812))+ISNUMBER(SEARCH("ПВХ-1",'8 (Отряд)'!$H$1:$H$1812))+ISNUMBER(SEARCH("ПВХ-1Т",'8 (Отряд)'!$H$1:$H$1812))+ISNUMBER(SEARCH("ПВХ-3",'8 (Отряд)'!$H$1:$H$1812))+ISNUMBER(SEARCH("ПВХ-3Т",'8 (Отряд)'!$H$1:$H$1812))+ISNUMBER(SEARCH("Бумеранг-10 (День)",'8 (Отряд)'!$H$1:$H$1812))+ISNUMBER(SEARCH("Бумеранг-10 (Ночь)",'8 (Отряд)'!$H$1:$H$1812))+ISNUMBER(SEARCH("ПВХ-5",'8 (Отряд)'!$H$1:$H$1812))+ISNUMBER(SEARCH("ПВХ-5Т",'8 (Отряд)'!$H$1:$H$1812)))>0)*('8 (Отряд)'!$M$1:$M$1812="уничтожение")*('8 (Отряд)'!$N$1:$N$1812="уничтожено"))} -> 0 | G33: {=SUMPRODUCT(('8 (Отряд)'!C1:C1812="пункт управления")*((ISNUMBER(SEARCH("Молния-2",'8 (Отряд)'!H1:H1812))+ISNUMBER(SEARCH("Молния-2ДТ",'8 (Отряд)'!H1:H1812))+ISNUMBER(SEARCH("Утка Д",'8 (Отряд)'!H1:H1812))+ISNUMBER(SEARCH("Утка Н",'8 (Отряд)'!H1:H1812))+ISNUMBER(SEARCH("Ш-10",'8 (Отряд)'!H1:H1812))+ISNUMBER(SEARCH("Х-51",'8 (Отряд)'!H1:H1812))+ISNUMBER(SEARCH("Х-52",'8 (Отряд)'!H1:H1812))+ISNUMBER(SEARCH("Скальпель",'8 (Отряд)'!H1:H1812)))>0)*('8 (Отряд)'!M1:M1812="уничтожение")*('8 (Отряд)'!N1:N1812="уничтожено"))} -> 0 | I33: =G33+E33 -> 0
A34: склад БК | E34: {=SUMPRODUCT(('8 (Отряд)'!$C$1:$C$1812=A34)*((ISNUMBER(SEARCH("КВН",'8 (Отряд)'!$H$1:$H$1812))+ISNUMBER(SEARCH("КВН-Т",'8 (Отряд)'!$H$1:$H$1812))+ISNUMBER(SEARCH("ПВХ-1",'8 (Отряд)'!$H$1:$H$1812))+ISNUMBER(SEARCH("ПВХ-1Т",'8 (Отряд)'!$H$1:$H$1812))+ISNUMBER(SEARCH("ПВХ-3",'8 (Отряд)'!$H$1:$H$1812))+ISNUMBER(SEARCH("ПВХ-3Т",'8 (Отряд)'!$H$1:$H$1812))+ISNUMBER(SEARCH("Бумеранг-10 (День)",'8 (Отряд)'!$H$1:$H$1812))+ISNUMBER(SEARCH("Бумеранг-10 (Ночь)",'8 (Отряд)'!$H$1:$H$1812))+ISNUMBER(SEARCH("ПВХ-5",'8 (Отряд)'!$H$1:$H$1812))+ISNUMBER(SEARCH("ПВХ-5Т",'8 (Отряд)'!$H$1:$H$1812)))>0)*('8 (Отряд)'!$M$1:$M$1812="уничтожение")*('8 (Отряд)'!$N$1:$N$1812="уничтожено"))} -> 0 | G34: {=SUMPRODUCT(('8 (Отряд)'!C1:C1812="склад БК")*((ISNUMBER(SEARCH("Молния-2",'8 (Отряд)'!H1:H1812))+ISNUMBER(SEARCH("Молния-2ДТ",'8 (Отряд)'!H1:H1812))+ISNUMBER(SEARCH("Утка Д",'8 (Отряд)'!H1:H1812))+ISNUMBER(SEARCH("Утка Н",'8 (Отряд)'!H1:H1812))+ISNUMBER(SEARCH("Ш-10",'8 (Отряд)'!H1:H1812))+ISNUMBER(SEARCH("Х-51",'8 (Отряд)'!H1:H1812))+ISNUMBER(SEARCH("Х-52",'8 (Отряд)'!H1:H1812))+ISNUMBER(SEARCH("Скальпель",'8 (Отряд)'!H1:H1812)))>0)*('8 (Отряд)'!M1:M1812="уничтожение")*('8 (Отряд)'!N1:N1812="уничтожено"))} -> 0 | I34: =G34+E34 -> 0
A35: склад ГСМ | E35: {=SUMPRODUCT(('8 (Отряд)'!$C$1:$C$1812=A35)*((ISNUMBER(SEARCH("КВН",'8 (Отряд)'!$H$1:$H$1812))+ISNUMBER(SEARCH("КВН-Т",'8 (Отряд)'!$H$1:$H$1812))+ISNUMBER(SEARCH("ПВХ-1",'8 (Отряд)'!$H$1:$H$1812))+ISNUMBER(SEARCH("ПВХ-1Т",'8 (Отряд)'!$H$1:$H$1812))+ISNUMBER(SEARCH("ПВХ-3",'8 (Отряд)'!$H$1:$H$1812))+ISNUMBER(SEARCH("ПВХ-3Т",'8 (Отряд)'!$H$1:$H$1812))+ISNUMBER(SEARCH("Бумеранг-10 (День)",'8 (Отряд)'!$H$1:$H$1812))+ISNUMBER(SEARCH("Бумеранг-10 (Ночь)",'8 (Отряд)'!$H$1:$H$1812))+ISNUMBER(SEARCH("ПВХ-5",'8 (Отряд)'!$H$1:$H$1812))+ISNUMBER(SEARCH("ПВХ-5Т",'8 (Отряд)'!$H$1:$H$1812)))>0)*('8 (Отряд)'!$M$1:$M$1812="уничтожение")*('8 (Отряд)'!$N$1:$N$1812="уничтожено"))} -> 0 | G35: {=SUMPRODUCT(('8 (Отряд)'!C1:C1812="склад ГСМ")*((ISNUMBER(SEARCH("Молния-2",'8 (Отряд)'!H1:H1812))+ISNUMBER(SEARCH("Молния-2ДТ",'8 (Отряд)'!H1:H1812))+ISNUMBER(SEARCH("Утка Д",'8 (Отряд)'!H1:H1812))+ISNUMBER(SEARCH("Утка Н",'8 (Отряд)'!H1:H1812))+ISNUMBER(SEARCH("Ш-10",'8 (Отряд)'!H1:H1812))+ISNUMBER(SEARCH("Х-51",'8 (Отряд)'!H1:H1812))+ISNUMBER(SEARCH("Х-52",'8 (Отряд)'!H1:H1812))+ISNUMBER(SEARCH("Скальпель",'8 (Отряд)'!H1:H1812)))>0)*('8 (Отряд)'!M1:M1812="уничтожение")*('8 (Отряд)'!N1:N1812="уничтожено"))} -> 0 | I35: =G35+E35 -> 0
A36: огневая позиция | E36: {=SUMPRODUCT(('8 (Отряд)'!$C$1:$C$1812=A36)*((ISNUMBER(SEARCH("КВН",'8 (Отряд)'!$H$1:$H$1812))+ISNUMBER(SEARCH("КВН-Т",'8 (Отряд)'!$H$1:$H$1812))+ISNUMBER(SEARCH("ПВХ-1",'8 (Отряд)'!$H$1:$H$1812))+ISNUMBER(SEARCH("ПВХ-1Т",'8 (Отряд)'!$H$1:$H$1812))+ISNUMBER(SEARCH("ПВХ-3",'8 (Отряд)'!$H$1:$H$1812))+ISNUMBER(SEARCH("ПВХ-3Т",'8 (Отряд)'!$H$1:$H$1812))+ISNUMBER(SEARCH("Бумеранг-10 (День)",'8 (Отряд)'!$H$1:$H$1812))+ISNUMBER(SEARCH("Бумеранг-10 (Ночь)",'8 (Отряд)'!$H$1:$H$1812))+ISNUMBER(SEARCH("ПВХ-5",'8 (Отряд)'!$H$1:$H$1812))+ISNUMBER(SEARCH("ПВХ-5Т",'8 (Отряд)'!$H$1:$H$1812)))>0)*('8 (Отряд)'!$M$1:$M$1812="уничтожение")*('8 (Отряд)'!$N$1:$N$1812="уничтожено"))} -> 0 | G36: {=SUMPRODUCT(('8 (Отряд)'!C1:C1812="огневая позиция")*((ISNUMBER(SEARCH("Молния-2",'8 (Отряд)'!H1:H1812))+ISNUMBER(SEARCH("Молния-2ДТ",'8 (Отряд)'!H1:H1812))+ISNUMBER(SEARCH("Утка Д",'8 (Отряд)'!H1:H1812))+ISNUMBER(SEARCH("Утка Н",'8 (Отряд)'!H1:H1812))+ISNUMBER(SEARCH("Ш-10",'8 (Отряд)'!H1:H1812))+ISNUMBER(SEARCH("Х-51",'8 (Отряд)'!H1:H1812))+ISNUMBER(SEARCH("Х-52",'8 (Отряд)'!H1:H1812))+ISNUMBER(SEARCH("Скальпель",'8 (Отряд)'!H1:H1812)))>0)*('8 (Отряд)'!M1:M1812="уничтожение")*('8 (Отряд)'!N1:N1812="уничтожено"))} -> 0 | I36: =G36+E36 -> 0
A37: пункт временной дислокации | E37: {=SUMPRODUCT(('8 (Отряд)'!$C$1:$C$1812=A37)*((ISNUMBER(SEARCH("КВН",'8 (Отряд)'!$H$1:$H$1812))+ISNUMBER(SEARCH("КВН-Т",'8 (Отряд)'!$H$1:$H$1812))+ISNUMBER(SEARCH("ПВХ-1",'8 (Отряд)'!$H$1:$H$1812))+ISNUMBER(SEARCH("ПВХ-1Т",'8 (Отряд)'!$H$1:$H$1812))+ISNUMBER(SEARCH("ПВХ-3",'8 (Отряд)'!$H$1:$H$1812))+ISNUMBER(SEARCH("ПВХ-3Т",'8 (Отряд)'!$H$1:$H$1812))+ISNUMBER(SEARCH("Бумеранг-10 (День)",'8 (Отряд)'!$H$1:$H$1812))+ISNUMBER(SEARCH("Бумеранг-10 (Ночь)",'8 (Отряд)'!$H$1:$H$1812))+ISNUMBER(SEARCH("ПВХ-5",'8 (Отряд)'!$H$1:$H$1812))+ISNUMBER(SEARCH("ПВХ-5Т",'8 (Отряд)'!$H$1:$H$1812)))>0)*('8 (Отряд)'!$M$1:$M$1812="уничтожение")*('8 (Отряд)'!$N$1:$N$1812="уничтожено"))} -> 0 | G37: {=SUMPRODUCT(('8 (Отряд)'!C1:C1812="пункт временной дислокации")*((ISNUMBER(SEARCH("Молния-2",'8 (Отряд)'!H1:H1812))+ISNUMBER(SEARCH("Молния-2ДТ",'8 (Отряд)'!H1:H1812))+ISNUMBER(SEARCH("Утка Д",'8 (Отряд)'!H1:H1812))+ISNUMBER(SEARCH("Утка Н",'8 (Отряд)'!H1:H1812))+ISNUMBER(SEARCH("Ш-10",'8 (Отряд)'!H1:H1812))+ISNUMBER(SEARCH("Х-51",'8 (Отряд)'!H1:H1812))+ISNUMBER(SEARCH("Х-52",'8 (Отряд)'!H1:H1812))+ISNUMBER(SEARCH("Скальпель",'8 (Отряд)'!H1:H1812)))>0)*('8 (Отряд)'!M1:M1812="уничтожение")*('8 (Отряд)'!N1:N1812="уничтожено"))} -> 0 | I37: =G37+E37 -> 0
A38: инженерное сооружение | E38: {=SUMPRODUCT(('8 (Отряд)'!$C$1:$C$1812=A38)*((ISNUMBER(SEARCH("КВН",'8 (Отряд)'!$H$1:$H$1812))+ISNUMBER(SEARCH("КВН-Т",'8 (Отряд)'!$H$1:$H$1812))+ISNUMBER(SEARCH("ПВХ-1",'8 (Отряд)'!$H$1:$H$1812))+ISNUMBER(SEARCH("ПВХ-1Т",'8 (Отряд)'!$H$1:$H$1812))+ISNUMBER(SEARCH("ПВХ-3",'8 (Отряд)'!$H$1:$H$1812))+ISNUMBER(SEARCH("ПВХ-3Т",'8 (Отряд)'!$H$1:$H$1812))+ISNUMBER(SEARCH("Бумеранг-10 (День)",'8 (Отряд)'!$H$1:$H$1812))+ISNUMBER(SEARCH("Бумеранг-10 (Ночь)",'8 (Отряд)'!$H$1:$H$1812))+ISNUMBER(SEARCH("ПВХ-5",'8 (Отряд)'!$H$1:$H$1812))+ISNUMBER(SEARCH("ПВХ-5Т",'8 (Отряд)'!$H$1:$H$1812)))>0)*('8 (Отряд)'!$M$1:$M$1812="уничтожение")*('8 (Отряд)'!$N$1:$N$1812="уничтожено"))} -> 0 | G38: {=SUMPRODUCT(('8 (Отряд)'!C2:C1813="инженерное сооружение")*((ISNUMBER(SEARCH("Молния-2",'8 (Отряд)'!H2:H1813))+ISNUMBER(SEARCH("Молния-2ДТ",'8 (Отряд)'!H2:H1813))+ISNUMBER(SEARCH("Утка Д",'8 (Отряд)'!H2:H1813))+ISNUMBER(SEARCH("Утка Н",'8 (Отряд)'!H2:H1813))+ISNUMBER(SEARCH("Ш-10",'8 (Отряд)'!H2:H1813))+ISNUMBER(SEARCH("Х-51",'8 (Отряд)'!H2:H1813))+ISNUMBER(SEARCH("Х-52",'8 (Отряд)'!H2:H1813))+ISNUMBER(SEARCH("Скальпель",'8 (Отряд)'!H2:H1813)))>0)*('8 (Отряд)'!M2:M1813="уничтожение")*('8 (Отряд)'!N2:N1813="уничтожено"))} -> 0 | I38: =G38+E38 -> 0
A39: система связи | E39: {=SUMPRODUCT(('8 (Отряд)'!$C$1:$C$1812=A39)*((ISNUMBER(SEARCH("КВН",'8 (Отряд)'!$H$1:$H$1812))+ISNUMBER(SEARCH("КВН-Т",'8 (Отряд)'!$H$1:$H$1812))+ISNUMBER(SEARCH("ПВХ-1",'8 (Отряд)'!$H$1:$H$1812))+ISNUMBER(SEARCH("ПВХ-1Т",'8 (Отряд)'!$H$1:$H$1812))+ISNUMBER(SEARCH("ПВХ-3",'8 (Отряд)'!$H$1:$H$1812))+ISNUMBER(SEARCH("ПВХ-3Т",'8 (Отряд)'!$H$1:$H$1812))+ISNUMBER(SEARCH("Бумеранг-10 (День)",'8 (Отряд)'!$H$1:$H$1812))+ISNUMBER(SEARCH("Бумеранг-10 (Ночь)",'8 (Отряд)'!$H$1:$H$1812))+ISNUMBER(SEARCH("ПВХ-5",'8 (Отряд)'!$H$1:$H$1812))+ISNUMBER(SEARCH("ПВХ-5Т",'8 (Отряд)'!$H$1:$H$1812)))>0)*('8 (Отряд)'!$M$1:$M$1812="уничтожение")*('8 (Отряд)'!$N$1:$N$1812="уничтожено"))} -> 0 | G39: {=SUMPRODUCT(('8 (Отряд)'!C1:C1812="система связи")*((ISNUMBER(SEARCH("Молния-2",'8 (Отряд)'!H1:H1812))+ISNUMBER(SEARCH("Молния-2ДТ",'8 (Отряд)'!H1:H1812))+ISNUMBER(SEARCH("Утка Д",'8 (Отряд)'!H1:H1812))+ISNUMBER(SEARCH("Утка Н",'8 (Отряд)'!H1:H1812))+ISNUMBER(SEARCH("Ш-10",'8 (Отряд)'!H1:H1812))+ISNUMBER(SEARCH("Х-51",'8 (Отряд)'!H1:H1812))+ISNUMBER(SEARCH("Х-52",'8 (Отряд)'!H1:H1812))+ISNUMBER(SEARCH("Скальпель",'8 (Отряд)'!H1:H1812)))>0)*('8 (Отряд)'!M1:M1812="уничтожение")*('8 (Отряд)'!N1:N1812="уничтожено"))} -> 0 | I39: =G39+E39 -> 0
A40: живая сила 200 | E40: {=SUMPRODUCT(('8 (Отряд)'!$C$1:$C$1812=A40)*((ISNUMBER(SEARCH("КВН",'8 (Отряд)'!$H$1:$H$1812))+ISNUMBER(SEARCH("КВН-Т",'8 (Отряд)'!$H$1:$H$1812))+ISNUMBER(SEARCH("ПВХ-1",'8 (Отряд)'!$H$1:$H$1812))+ISNUMBER(SEARCH("ПВХ-1Т",'8 (Отряд)'!$H$1:$H$1812))+ISNUMBER(SEARCH("ПВХ-3",'8 (Отряд)'!$H$1:$H$1812))+ISNUMBER(SEARCH("ПВХ-3Т",'8 (Отряд)'!$H$1:$H$1812))+ISNUMBER(SEARCH("Бумеранг-10 (День)",'8 (Отряд)'!$H$1:$H$1812))+ISNUMBER(SEARCH("Бумеранг-10 (Ночь)",'8 (Отряд)'!$H$1:$H$1812))+ISNUMBER(SEARCH("ПВХ-5",'8 (Отряд)'!$H$1:$H$1812))+ISNUMBER(SEARCH("ПВХ-5Т",'8 (Отряд)'!$H$1:$H$1812)))>0)*('8 (Отряд)'!$M$1:$M$1812="уничтожение")*('8 (Отряд)'!$N$1:$N$1812="уничтожено"))} -> 0 | G40: {=SUMPRODUCT(('8 (Отряд)'!C1:C1812="живая сила 200")*((ISNUMBER(SEARCH("Молния-2",'8 (Отряд)'!H1:H1812))+ISNUMBER(SEARCH("Молния-2ДТ",'8 (Отряд)'!H1:H1812))+ISNUMBER(SEARCH("Утка Д",'8 (Отряд)'!H1:H1812))+ISNUMBER(SEARCH("Утка Н",'8 (Отряд)'!H1:H1812))+ISNUMBER(SEARCH("Ш-10",'8 (Отряд)'!H1:H1812))+ISNUMBER(SEARCH("Х-51",'8 (Отряд)'!H1:H1812))+ISNUMBER(SEARCH("Х-52",'8 (Отряд)'!H1:H1812))+ISNUMBER(SEARCH("Скальпель",'8 (Отряд)'!H1:H1812)))>0)*('8 (Отряд)'!M1:M1812="уничтожение")*('8 (Отряд)'!N1:N1812="уничтожено"))} -> 0 | I40: =G40+E40 -> 0
...

Sheet 8 (Отряд)
A1: В полосе ответственности 2 ОА
A2: № п/п | B2: Время | C2: Характер цели | D2: уточнение | E2: координаты уничтоженой цели | G2: Ближайший н.п (уничтоженой цели) | H2: Тип дрона и расход | I2: кол-во дронов | J2: Вид БП и расход | K2: кол-во бп | L2: Вид взрывателя и расход | M2: цель применения | N2: Результат применения | O2: В чьих интересах
E3: Х | F3: У
A4: 0 | B4: 6:30-6:30 | C4: БпЛА | D4: FPV К.Т. FPV С.Т. | H4: ЧГ | M4: подавление | N4: успешно | O4: 2 ОА
A5: 1 | O5: 2 ОА
A6: 2 | O6: 2 ОА
A7: 3 | O7: 2 ОА
A8: 4 | O8: 2 ОА
A9: 5 | O9: 2 ОА
A10: 6 | O10: 2 ОА
A11: 7 | O11: 2 ОА
A12: 8 | O12: 2 ОА
A13: 9 | O13: 2 ОА
A14: 10 | O14: 2 ОА
A15: 11 | O15: 2 ОА
A16: 12 | O16: 2 ОА
... A304: 300 | O304: 2 ОА
A1772: 4 | B1772: F | C1772: 6166559923 | D1772: 32 | E1772: 4 | F1772: 13 | G1772: Молния-2ДТ | H1772: КОЗБЧ-5 | I1772: УДЗ | J1772: Патрулирование | K1772: 45903 | L1772: - | M1772: - | N1772: true | O1772: - | P1772: - | Q1772: Межова | R1772: 0.56041667
B1773: 13:37 | C1773: Патрулирование | D1773: ПВД | E1773: 1212123 | F1773: 2323234 | G1773: Межова | H1773: Молния-2 | I1773: 1 | J1773: КОЗБЧ-5 | K1773: 1 | L1773: УдивДД+МД5М | M1773: уничтожение | N1773: поражено | O1773: 2 ОА | P1773: Космос | Q1773: 33
B1774: 13:42 | C1774: Патрулирование | D1774: ПВД | E1774: 1212123 | F1774: 2121321 | G1774: Межова | H1774: Утка Н | I1774: 1 | J1774: КОЗБЧ-5 | K1774: 1 | L1774: УдивДД | M1774: уничтожение | N1774: поражено | O1774: 2 ОА | P1774: Космос | Q1774: 35

Sheet ИТОГО
B2: Красноармейское тактическое направление | E2: Суточная эфективность: | H2: =(F29+F30+F31+F32+F33+F34+F35+F36+F37+F38+F39+F40+F41+F42+F43)/(F7+F8+F9+F10+F11+F12+F13+F14+F15+F16+F17+F18+F19+F20+F21) -> #DIV/0! | N2: Внимание!!! В первую очередь перенеси данные со вчерашнего донесения
E3: Суммарная эфективность: | H3: ='Эффективность (...) дроны'!B52 -> 0.35684307 | N3: данные вписывать обязательно.Используются в подсчетах
N4: накопительная таблица за вчерашний день. Копировать и вставить со вчерашней | Q4: суммарная эфективность за вчерашний день.
B5: 1. Поражено: | E5: 2. Итого применено: | H5: 4. Накопительная таблица
B6: за сутки | E6: за сутки | H6: С 08:00 19.06.25 по 08:00 | I6: =главная!G4 -> 04.09.2025г.
B7: =главная!A13 -> танк | C7: =главная!I13 -> 0 | E7: =главная!B49 -> КВН | F7: =главная!D49 -> 0 | H7: танк | I7: =O7+C7 -> 2 | N7: =H7 -> танк | O7: 2 | Q7: На листе "Сумарно" вписать: 1. В верхнем столбце вписать количество примененных дронов(Итого примененно) 2. В нижнем столбце вписать количество успешных дронов. Таблица автоматически считает и выводит на лист Итого в Сумарную эффективность.
B8: =главная!A14 -> самоходное артиллерийское орудие | C8: =главная!I14 -> 0 | E8: =главная!B50 -> КВН-Т | F8: =главная!D50 -> 0 | H8: самоходное артиллерийское орудие | I8: =O8+C8 -> 0 | N8: =H8 -> самоходное артиллерийское орудие
B9: =главная!A15 -> буксируемое артиллерийское орудие | C9: =главная!I15 -> 0 | E9: =главная!B51 -> ПВХ-1 | F9: =главная!D51 -> 0 | H9: буксируемое артиллерийское орудие | I9: =O9+C9 -> 6 | N9: =H9 -> буксируемое артиллерийское орудие | O9: 6
B10: =главная!A16 -> РСЗО | C10: =главная!I16 -> 0 | E10: =главная!B52 -> ПВХ-1Т | F10: =главная!D52 -> 0 | H10: РСЗО | I10: =O10+C10 -> 0 | N10: =H10 -> РСЗО
B11: =главная!A17 -> миномет | C11: =главная!I17 -> 0 | E11: =главная!B53 -> ПВХ-1 Сумрак | F11: =главная!D53 -> 0 | H11: миномет | I11: =O11+C11 -> 1 | N11: =H11 -> миномет | O11: 1
B12: =главная!A18 -> ПТРК | C12: =главная!I18 -> 0 | E12: =главная!B54 -> ПВХ-3 | F12: =главная!D54 -> 0 | H12: ПТРК | I12: =O12+C12 -> 0 | N12: =H12 -> ПТРК
B13: =главная!A19 -> зенитная установка | C13: =главная!I19 -> 0 | E13: =главная!B55 -> ПВХ-3Т | F13: =главная!D55 -> 0 | H13: зенитная установка | I13: =O13+C13 -> 0 | N13: =H13 -> зенитная установка
B14: =главная!A20 -> боевая машина пехоты | C14: =главная!I20 -> 0 | E14: =главная!B56 -> Бумеранг-10 (День) | F14: =главная!D56 -> 0 | H14: боевая машина пехоты | I14: =O14+C14 -> 1 | N14: =H14 -> боевая машина пехоты | O14: 1
B15: =главная!A21 -> бронетранспортер | C15: =главная!I21 -> 0 | E15: =главная!B57 -> Бумеранг-10 (Ночь) | F15: =главная!D57 -> 0 | H15: бронетранспортер | I15: =O15+C15 -> 1 | N15: =H15 -> бронетранспортер | O15: 1
B16: =главная!A22 -> боевая бронированная машина | C16: =главная!I22 -> 0 | E16: =главная!B58 -> ПВХ-5 | F16: =главная!D58 -> 0 | H16: боевая бронированная машина | I16: =O16+C16 -> 12 | N16: =H16 -> боевая бронированная машина | O16: 12
B17: =главная!A23 -> РЛС | C17: =главная!I23 -> 0 | E17: =главная!B59 -> ПВХ-5Т | F17: =главная!D59 -> 0 | H17: РЛС | I17: =O17+C17 -> 2 | N17: =H17 -> РЛС | O17: 2
B18: =главная!A24 -> РЭР | C18: =главная!I24 -> 0 | E18: =главная!B60 -> Молния-2 | F18: =главная!D60 -> 0 | H18: РЭР | I18: =O18+C18 -> 0 | N18: =H18 -> РЭР
B19: =главная!A25 -> РЭБ | C19: =главная!I25 -> 0 | E19: =главная!B61 -> Молния-2ДТ | F19: =главная!D61 -> 0 | H19: РЭБ | I19: =O19+C19 -> 0 | N19: =H19 -> РЭБ
B20: =главная!A26 -> автомобильная техника | C20: =главная!I26 -> 0 | E20: =главная!B62 -> Ш-10 | F20: =главная!D62 -> 0 | H20: автомобильная техника | I20: =O20+C20 -> 143 | N20: =H20 -> автомобильная техника | O20: 143
B21: =главная!A27 -> мототехника | C21: =главная!I27 -> 0 | E21: =главная!B63 -> Х-51 | F21: =главная!D63 -> 0 | H21: мототехника | I21: =O21+C21 -> 1 | N21: =H21 -> мототехника | O21: 1
B22: =главная!A28 -> инженерная техника | C22: =главная!I28 -> 0 | E22: =главная!B64 -> Х-52 | F22: =главная!D64 -> 0 | H22: инженерная техника | I22: =O22+C22 -> 5 | N22: =H22 -> инженерная техника | O22: 5
B23: =главная!A29 -> ПУ БпЛА | C23: =главная!I29 -> 0 | E23: =главная!B65 -> Скальпель | F23: =главная!D65 -> 0 | H23: ПУ БпЛА | I23: =O23+C23 -> 95 | N23: =H23 -> ПУ БпЛА | O23: 95
B24: =главная!A30 -> БпЛА | C24: =главная!I30 -> 0 | E24: =главная!B66 -> Утка Д | F24: =главная!D66 -> 0 | H24: БпЛА | I24: =O24+C24 -> 42 | N24: =H24 -> БпЛА | O24: 42
B25: =главная!A31 -> Наземные дроны | C25: =главная!I31 -> 0 | E25: =главная!B67 -> Утка Н | F25: =главная!D67 -> 0 | H25: Наземные дроны | I25: =O25+C25 -> 5 | N25: =H25 -> Наземные дроны | O25: 5
B26: =главная!A32 -> Баба Яга | C26: =главная!I32 -> 0 | H26: Баба Яга | I26: =O26+C26 -> 100 | N26: =H26 -> Баба Яга | O26: 100
B27: =главная!A33 -> пункт управления | C27: =главная!I33 -> 0 | E27: 3. Успешные применения: | H27: пункт управления | I27: =O27+C27 -> 0 | N27: =H27 -> пункт управления
B28: =главная!A34 -> склад БК | C28: =главная!I34 -> 0 | E28: за сутки | H28: склад БК | I28: =O28+C28 -> 11 | N28: =H28 -> склад БК | O28: 11
B29: =главная!A35 -> склад ГСМ | C29: =главная!I35 -> 0 | E29: =главная!B49 -> КВН | F29: =SUMIFS('8 (Отряд)'!$I$1:$I$1812,'8 (Отряд)'!$H$1:$H$1812,"КВН",'8 (Отряд)'!$M$1:$M$1812,"уничтожение",'8 (Отряд)'!$N$1:$N$1812,"уничтожено")+SUMIFS('8 (Отряд)'!$I$1:$I$1812,'8 (Отряд)'!$H$1:$H$1812,"КВН",'8 (Отряд)'!$M$1:$M$1812,"уничтожение",'8 (Отряд)'!$N$1:$N$1812,"поражено") -> 0 | H29: склад ГСМ | I29: =O29+C29 -> 0 | N29: =H29 -> склад ГСМ
B30: =главная!A36 -> огневая позиция | C30: =главная!I36 -> 0 | E30: =главная!B50 -> КВН-Т | F30: =SUMIFS('8 (Отряд)'!$I$1:$I$1812,'8 (Отряд)'!$H$1:$H$1812,"КВН-Т",'8 (Отряд)'!$M$1:$M$1812,"уничтожение",'8 (Отряд)'!$N$1:$N$1812,"уничтожено")+SUMIFS('8 (Отряд)'!$I$1:$I$1812,'8 (Отряд)'!$H$1:$H$1812,"КВН-Т",'8 (Отряд)'!$M$1:$M$1812,"уничтожение",'8 (Отряд)'!$N$1:$N$1812,"поражено") -> 0 | H30: огневая позиция | I30: =O30+C30 -> 27 | N30: =H30 -> огневая позиция | O30: 27
B31: =главная!A37 -> пункт временной дислокации | C31: =главная!I37 -> 0 | E31: =главная!B51 -> ПВХ-1 | F31: =SUMIFS('8 (Отряд)'!$I$1:$I$1812,'8 (Отряд)'!$H$1:$H$1812,"ПВХ-1",'8 (Отряд)'!$M$1:$M$1812,"уничтожение",'8 (Отряд)'!$N$1:$N$1812,"уничтожено")+SUMIFS('8 (Отряд)'!$I$1:$I$1812,'8 (Отряд)'!$H$1:$H$1812,"ПВХ-1",'8 (Отряд)'!$M$1:$M$1812,"уничтожение",'8 (Отряд)'!$N$1:$N$1812,"поражено") -> 0 | H31: пункт временной дислокации | I31: =O31+C31 -> 189 | N31: =H31 -> пункт временной дислокации | O31: 189
B32: =главная!A38 -> инженерное сооружение | C32: =главная!I38 -> 0 | E32: =главная!B52 -> ПВХ-1Т | F32: =SUMIFS('8 (Отряд)'!$I$1:$I$1812,'8 (Отряд)'!$H$1:$H$1812,"ПВХ-1Т",'8 (Отряд)'!$M$1:$M$1812,"уничтожение",'8 (Отряд)'!$N$1:$N$1812,"уничтожено")+SUMIFS('8 (Отряд)'!$I$1:$I$1812,'8 (Отряд)'!$H$1:$H$1812,"ПВХ-1Т",'8 (Отряд)'!$M$1:$M$1812,"уничтожение",'8 (Отряд)'!$N$1:$N$1812,"поражено") -> 0 | H32: инженерное сооружение | I32: =O32+C32 -> 3 | N32: =H32 -> инженерное сооружение | O32: 3
B33: =главная!A39 -> система связи | C33: =главная!I39 -> 0 | E33: =главная!B53 -> ПВХ-1 Сумрак | F33: =SUMIFS('8 (Отряд)'!$I$1:$I$1812,'8 (Отряд)'!$H$1:$H$1812,"ПВХ-1 Сумрак",'8 (Отряд)'!$M$1:$M$1812,"уничтожение",'8 (Отряд)'!$N$1:$N$1812,"уничтожено")+SUMIFS('8 (Отряд)'!$I$1:$I$1812,'8 (Отряд)'!$H$1:$H$1812,"ПВХ-1 Сумрак",'8 (Отряд)'!$M$1:$M$1812,"уничтожение",'8 (Отряд)'!$N$1:$N$1812,"поражено") -> 0 | H33: система связи | I33: =O33+C33 -> 156 | N33: =H33 -> система связи | O33: 156
B34: =главная!A40 -> живая сила 200 | C34: =главная!I40 -> 0 | E34: =главная!B54 -> ПВХ-3 | F34: =SUMIFS('8 (Отряд)'!$I$1:$I$1812,'8 (Отряд)'!$H$1:$H$1812,"ПВХ-3",'8 (Отряд)'!$M$1:$M$1812,"уничтожение",'8 (Отряд)'!$N$1:$N$1812,"уничтожено")+SUMIFS('8 (Отряд)'!$I$1:$I$1812,'8 (Отряд)'!$H$1:$H$1812,"ПВХ-3",'8 (Отряд)'!$M$1:$M$1812,"уничтожение",'8 (Отряд)'!$N$1:$N$1812,"поражено") -> 0 | H34: живая сила 200 | I34: =O34+C34 -> 9 | N34: =H34 -> живая сила 200 | O34: 9
B35: =главная!A41 -> живая сила 300 | C35: =главная!I41 -> 0 | E35: =главная!B55 -> ПВХ-3Т | F35: =SUMIFS('8 (Отряд)'!$I$1:$I$1812,'8 (Отряд)'!$H$1:$H$1812,"ПВХ-3Т",'8 (Отряд)'!$M$1:$M$1812,"уничтожение",'8 (Отряд)'!$N$1:$N$1812,"уничтожено")+SUMIFS('8 (Отряд)'!$I$1:$I$1812,'8 (Отряд)'!$H$1:$H$1812,"ПВХ-3Т",'8 (Отряд)'!$M$1:$M$1812,"уничтожение",'8 (Отряд)'!$N$1:$N$1812,"поражено") -> 0 | H35: живая сила 300 | I35: =O35+C35 -> 22 | N35: =H35 -> живая сила 300 | O35: 22
B36: =главная!A42 -> средства жизнеобеспечения | C36: =главная!I42 -> 0 | E36: =главная!B56 -> Бумеранг-10 (День) | F36: =SUMIFS('8 (Отряд)'!$I$1:$I$1812,'8 (Отряд)'!$H$1:$H$1812,"Бумеранг-10 (День)",'8 (Отряд)'!$M$1:$M$1812,"уничтожение",'8 (Отряд)'!$N$1:$N$1812,"уничтожено")+SUMIFS('8 (Отряд)'!$I$1:$I$1812,'8 (Отряд)'!$H$1:$H$1812,"Бумеранг-10 (День)",'8 (Отряд)'!$M$1:$M$1812,"уничтожение",'8 (Отряд)'!$N$1:$N$1812,"поражено") -> 0 | H36: средства жизнеобеспечения | I36: =O36+C36 -> 19 | N36: =H36 -> средства жизнеобеспечения | O36: 19
B37: =главная!A43 -> огневые средства | C37: =главная!I43 -> 0 | E37: =главная!B57 -> Бумеранг-10 (Ночь) | F37: =SUMIFS('8 (Отряд)'!$I$1:$I$1812,'8 (Отряд)'!$H$1:$H$1812,"Бумеранг-10 (Ночь)",'8 (Отряд)'!$M$1:$M$1812,"уничтожение",'8 (Отряд)'!$N$1:$N$1812,"уничтожено")+SUMIFS('8 (Отряд)'!$I$1:$I$1812,'8 (Отряд)'!$H$1:$H$1812,"Бумеранг-10 (Ночь)",'8 (Отряд)'!$M$1:$M$1812,"уничтожение",'8 (Отряд)'!$N$1:$N$1812,"поражено") -> 0 | H37: огневые средства | I37: =O37+C37 -> 0 | N37: =H37 -> огневые средства
B38: =главная!A44 -> макет | C38: =главная!I44 -> 0 | E38: =главная!B58 -> ПВХ-5 | F38: =SUMIFS('8 (Отряд)'!$I$1:$I$1812,'8 (Отряд)'!$H$1:$H$1812,"ПВХ-5",'8 (Отряд)'!$M$1:$M$1812,"уничтожение",'8 (Отряд)'!$N$1:$N$1812,"уничтожено")+SUMIFS('8 (Отряд)'!$I$1:$I$1812,'8 (Отряд)'!$H$1:$H$1812,"ПВХ-5",'8 (Отряд)'!$M$1:$M$1812,"уничтожение",'8 (Отряд)'!$N$1:$N$1812,"поражено") -> 0 | H38: макет | I38: =O38+C38 -> 3 | N38: =H38 -> макет | O38: 3
B39: =главная!A45 -> системой РЭБ "черный глаз" подавлено | C39: =главная!I45 -> 0 | E39: =главная!B59 -> ПВХ-5Т | F39: =SUMIFS('8 (Отряд)'!$I$1:$I$1812,'8 (Отряд)'!$H$1:$H$1812,"ПВХ-5Т",'8 (Отряд)'!$M$1:$M$1812,"уничтожение",'8 (Отряд)'!$N$1:$N$1812,"уничтожено")+SUMIFS('8 (Отряд)'!$I$1:$I$1812,'8 (Отряд)'!$H$1:$H$1812,"ПВХ-5Т",'8 (Отряд)'!$M$1:$M$1812,"уничтожение",'8 (Отряд)'!$N$1:$N$1812,"поражено") -> 0 | H39: РЭБ "черный глаз" подавлено | I39: =O39+C39 -> 2568 | N39: =H39 -> РЭБ "черный глаз" подавлено | O39: 2568
E40: =главная!B60 -> Молния-2 | F40: =SUMIFS('8 (Отряд)'!$I$1:$I$1812,'8 (Отряд)'!$H$1:$H$1812,"Молния-2",'8 (Отряд)'!$M$1:$M$1812,"уничтожение",'8 (Отряд)'!$N$1:$N$1812,"уничтожено")+SUMIFS('8 (Отряд)'!$I$1:$I$1812,'8 (Отряд)'!$H$1:$H$1812,"Молния-2",'8 (Отряд)'!$M$1:$M$1812,"уничтожение",'8 (Отряд)'!$N$1:$N$1812,"поражено") -> 0
E41: =главная!B61 -> Молния-2ДТ | F41: =SUMIFS('8 (Отряд)'!$I$1:$I$1812,'8 (Отряд)'!$H$1:$H$1812,"Молния-2ДТ",'8 (Отряд)'!$M$1:$M$1812,"уничтожение",'8 (Отряд)'!$N$1:$N$1812,"уничтожено")+SUMIFS('8 (Отряд)'!$I$1:$I$1812,'8 (Отряд)'!$H$1:$H$1812,"Молния-2ДТ",'8 (Отряд)'!$M$1:$M$1812,"уничтожение",'8 (Отряд)'!$N$1:$N$1812,"поражено") -> 0
...

Sheet Эффективность (...) дроны
A1: Подсчет по донесениям в ГБУ
A2: Всего … | B2: 45827 | C2: 45828 | D2: 45829 | E2: 45830 | F2: 45831 | G2: 45832 | H2: 45833 | I2: 45834 | J2: 45835 | K2: 45836 | L2: 45837 | M2: 45838 | N2: 45839 | O2: 45840 | P2: 45841 | Q2: 45842 | R2: 45843 | S2: 45844 | T2: 45845 | U2: 45846 | V2: 45847 | W2: 45848 | X2: 45849 | Y2: 45850 | Z2: 45851 | AA2: 45852 | AB2: 45853 | AC2: 45854 | AD2: 45855 | AE2: 45856 | AF2: 45857 | AG2: 45858 | AH2: 45859 | AI2: 45860 | AJ2: 45861 | AK2: 45862 | AL2: 45863 | AM2: 45864 | AN2: 45865 | AO2: 45866 | AP2: 45867 | AQ2: 45868 | AR2: 45869 | AS2: 45870 | AT2: 45871 | AU2: 45872 | AV2: 45873 | AW2: 45874 | AX2: 45875 | AY2: 45876 | AZ2: 45877 | BA2: 45878 | BB2: 45879 | BC2: 45880 | BD2: 45881 | BE2: 45882 | BF2: 45883 | BG2: 45884 | BH2: 45885 | BI2: 45886 | BJ2: 45887 | BK2: 45888 | BL2: 45889 | BM2: 45890 | BN2: 45891 | BO2: 45892 | BP2: 45893 | BQ2: 45894 | BR2: 45895 | BS2: 45896 | BT2: 45897 | BU2: 45898 | BV2: 45899 | BW2: 45900 | BX2: 45901 | BY2: 45902 | BZ2: 45903 | CA2: 45904 | CB2: 45905 | CC2: 45906 | CD2: 45907 | CE2: 45908 | CF2: 45909 | CG2: 45910 | CH2: 45911 | CI2: 45912 | CJ2: 45913 | CK2: 45914 | CL2: 45915 | CM2: 45916 | CN2: 45917 | CO2: 45918 | CP2: 45919 | CQ2: 45920 | CR2: 45921 | CS2: 45922 | CT2: 45923 | CU2: 45924 | CV2: 45925 | CW2: 45926 | CX2: 45927 | CY2: 45928 | CZ2: 45929 | DA2: 45930 | DB2: 45931 | DC2: 45932 | DD2: 45933 | DE2: 45934 | DF2: 45935 | DG2: 45936 | DH2: 45937 | DI2: 45938 | DJ2: 45939 | DK2: 45940 | DL2: 45941 | DM2: 45942 | DN2: 45943 | DO2: 45944 | DP2: 45945 | DQ2: 45946 | DR2: 45947 | DS2: 45948 | DT2: 45949 | DU2: 45950 | DV2: 45951 | DW2: 45952 | DX2: 45953 | DY2: 45954 | DZ2: 45955 | EA2: 45956 | EB2: 45957 | EC2: 45958 | ED2: 45959 | EE2: 45960 | EF2: 45961 | EG2: 45962 | EH2: 45963 | EI2: 45964 | EJ2: 45965 | EK2: 45966 | EL2: 45967 | EM2: 45968 | EN2: 45969 | EO2: 45970 | EP2: 45971 | EQ2: 45972 | ER2: 45973 | ES2: 45974 | ET2: 45975 | EU2: 45976
A3: КВН | P3: 1 | Q3: 3 | R3: 2 | S3: 4 | T3: 5 | U3: 5 | V3: 2 | W3: 4 | X3: 6 | Y3: 3 | Z3: 9 | AA3: 5 | AB3: 5 | AC3: 6 | BH3: 4 | BI3: 13 | BJ3: 12 | BK3: 7 | BL3: 11 | BM3: 12 | BN3: 5 | BO3: 6 | BP3: 5 | BQ3: 9 | BR3: 5 | BS3: 6 | BT3: 10 | BU3: 8 | BV3: 11 | BW3: 8 | BX3: 8 | BY3: 8 | BZ3: 6
A4: КВН-Т | V4: 3 | X4: 2 | Y4: 1 | Z4: 2 | AB4: 2 | AC4: 5 | AD4: 2
A5: ПВХ-1 | B5: 12 | C5: 10 | D5: 6 | E5: 36 | F5: 34 | G5: 21 | H5: 26 | I5: 9 | J5: 10 | K5: 31 | L5: 29 | M5: 40 | N5: 29 | O5: 24 | P5: 11 | Q5: 20 | R5: 27 | S5: 30 | T5: 44 | U5: 36 | V5: 34 | W5: 108 | X5: 47 | Y5: 55 | Z5: 61 | AA5: 64 | AB5: 35 | AC5: 74 | AD5: 102 | AE5: 57 | AF5: 48 | AG5: 35 | AH5: 34 | AI5: 11 | AJ5: 46 | AK5: 19 | AL5: 18 | AM5: 43 | AN5: 64 | AO5: 54 | AP5: 75 | AQ5: 73 | AR5: 75 | AS5: 45 | AT5: 36 | AU5: 56 | AV5: 6 | AW5: 35 | AX5: =[3]главная!D51 -> 82 | AY5: 67 | AZ5: 41 | BA5: 70 | BB5: 78 | BC5: 81 | BD5: 70 | BE5: 82 | BF5: 69 | BG5: 102 | BH5: 104 | BI5: 105 | BJ5: 86 | BK5: 56 | BL5: 47 | BM5: 46 | BN5: 105 | BO5: 44 | BP5: 48 | BQ5: 71 | BR5: 65 | BS5: 105 | BT5: 49 | BU5: 56 | BV5: 64 | BW5: 48 | BX5: 39 | BY5: 45 | BZ5: 53
A6: ПВХ-1Т | C6: 1 | D6: 18 | E6: 26 | F6: 17 | G6: 25 | H6: 24 | I6: 18 | J6: 29 | K6: 26 | L6: 20 | M6: 38 | N6: 35 | O6: 25 | P6: 26 | Q6: 31 | R6: 36 | S6: 45 | T6: 51 | U6: 51 | V6: 53 | W6: 51 | X6: 37 | Y6: 40 | Z6: 44 | AA6: 34 | AB6: 35 | AC6: 46 | AD6: 45 | AE6: 55 | AF6: 47 | AG6: 35 | AH6: 34 | AI6: 22 | AJ6: 23 | AK6: 32 | AL6: 30 | AM6: 52 | AN6: 65 | AO6: 74 | AP6: 58 | AQ6: 56 | AR6: 38 | AS6: 46 | AT6: 35 | AU6: 35 | AV6: 6 | AW6: 41 | AX6: =[3]главная!D52 -> 41 | AY6: 47 | AZ6: 38 | BA6: 61 | BB6: 53 | BC6: 67 | BD6: 34 | BE6: 41 | BF6: 48 | BG6: 66 | BH6: 48 | BI6: 75 | BJ6: 55 | BK6: 57 | BL6: 29 | BM6: 51 | BN6: 58 | BO6: 32 | BP6: 37 | BQ6: 42 | BR6: 58 | BS6: 58 | BT6: 67 | BU6: 67 | BV6: 62 | BW6: 58 | BX6: 60 | BY6: 45 | BZ6: 66
A7: ПВХ-1 "Сумрак"
A8: ПВХ-3
A9: ПВХ-3Т
A10: Бумеранг-10 (День) | BF10: 10 | BS10: 4 | BT10: 5 | BU10: 16 | BV10: 8 | BW10: 19 | BX10: 18 | BY10: 1
A11: Бумеранг-10 (Ночь)
A12: ПВХ-5
A13: ПВХ-5Т
A14: Молния-2 | E14: 10 | F14: 10 | G14: 6 | H14: 13 | I14: 19 | J14: 5 | K14: 26 | L14: 21 | M14: 24 | N14: 17 | O14: 21 | P14: 7 | Q14: 8 | R14: 1 | S14: 3 | T14: 9 | U14: 25 | V14: 27 | W14: 18 | X14: 19 | Y14: 19 | Z14: 29 | AA14: 22 | AB14: 8 | AD14: 14 | AE14: 8 | AG14: 6 | AH14: 6 | AI14: 9 | AJ14: 12 | AK14: 20 | AL14: 22 | AM14: 21 | AN14: 17 | AO14: 22 | AP14: 38 | AQ14: 30 | AR14: 26 | AT14: 5 | AX14: 38 | AY14: 8 | AZ14: 31 | BA14: 38 | BB14: 34 | BC14: 33 | BD14: 29 | BE14: 38 | BF14: 24 | BG14: 33 | BH14: 39 | BI14: 40 | BJ14: 25 | BK14: 35 | BL14: 29 | BM14: 19 | BN14: 52 | BO14: 35 | BP14: 30 | BQ14: 45 | BR14: 46 | BS14: 62 | BT14: 35 | BU14: 45 | BV14: 37 | BW14: 38 | BX14: 40 | BY14: 41 | BZ14: 50
A15: Молния-2ДТ | D15: 7 | E15: 5 | F15: 4 | G15: 12 | H15: 21 | I15: 23 | J15: 23 | K15: 24 | L15: 25 | M15: 9 | N15: 23 | O15: 7 | P15: 10 | Q15: 21 | R15: 2 | T15: 4 | U15: 14 | V15: 10 | W15: 11 | X15: 17 | Y15: 29 | Z15: 24 | AA15: 31 | AB15: 13 | AC15: 13 | AD15: 17 | AF15: 16 | AH15: 12 | AI15: 13 | AJ15: 14 | AK15: 20 | AN15: 16 | AP15: 15 | AQ15: 2 | AR15: 16 | AS15: 19 | AT15: 15 | AU15: 11 | AV15: 15 | AY15: 21 | AZ15: 18 | BA15: 21 | BB15: 20 | BC15: 25 | BD15: 18 | BE15: 23 | BF15: 33 | BG15: 24 | BH15: 22 | BI15: 24 | BJ15: 58 | BK15: 36 | BL15: 43 | BM15: 29 | BN15: 17 | BO15: 36 | BP15: 26 | BQ15: 20 | BR15: 24 | BS15: 25 | BT15: 18 | BU15: 35 | BV15: 42 | BW15: 7 | BX15: 30 | BY15: 23 | BZ15: 9
A16: ОСА 10-15
A17: ОСА 10-30
A18: Молния-2 ИИ
A19: Утка Д | Q19: 6 | R19: 20 | S19: 15 | T19: 1 | AB19: 5 | AC19: 13 | AD19: 19 | AF19: 13 | AG19: 2 | AH19: 17 | AI19: 19 | AJ19: 11 | AK19: 15 | AL19: 4 | AP19: 5 | AS19: 11 | AT19: 14 | AU19: 18 | AV19: 3 | AW19: 25 | AX19: 21 | AY19: 10
A20: Утка Н | Q20: 5 | R20: 9 | S20: 10 | T20: 18 | U20: 10 | V20: 17 | AE20: 30 | AF20: 18 | AG20: 9 | AH20: 9 | AI20: 7 | AJ20: 4 | AL20: 6 | AM20: 5 | AN20: 15 | AO20: 17 | AP20: 6 | AQ20: 15 | AR20: 31 | AS20: 7 | AV20: 1 | AY20: 2 | BD20: 2 | BG20: 5 | BY20: 1
A21: X51 | S21: 2 | V21: 1 | X21: 3 | AD21: 1 | AP21: 2 | AQ21: 1 | AS21: 1 | BC21: 2 | BD21: 2 | BF21: 3 | BM21: 1 | BP21: 1 | BR21: 4 | BU21: 1 | BY21: 1
A22: Х52 | AS22: 1 | BA22: 2 | BE22: 3 | BL22: 1 | BM22: 1 | BN22: 1
A23: Всего | B23: =SUM(B3:B22) -> 12 | C23: =SUM(C3:C22) -> 11 | D23: =SUM(D3:D22) -> 31 | E23: =SUM(E3:E22) -> 77 | F23: =SUM(F3:F22) -> 65 | G23: =SUM(G3:G22) -> 64 | H23: =SUM(H3:H22) -> 84 | I23: =SUM(I3:I22) -> 69 | ... EU23: =SUM(EU3:EU22) -> 0
A24: Успешные … | B24: 45827 | C24: 45828 | D24: 45829 | E24: 45830 | F24: 45831 | G24: 45832 | H24: 45833 | I24: 45834 | J24: 45835 | K24: 45836 | L24: 45837 | M24: 45838 | N24: 45839 | O24: 45840 | P24: 45841 | Q24: 45842 | R24: 45843 | S24: 45844 | T24: 45845 | U24: 45846 | V24: 45847 | W24: 45848 | X24: 45849 | Y24: 45850 | Z24: 45851 | AA24: 45852 | AB24: 45853 | AC24: 45854 | AD24: 45855 | AE24: 45856 | AF24: 45857 | AG24: 45858 | AH24: 45859 | AI24: 45860 | AJ24: 45861 | AK24: 45862 | AL24: 45863 | AM24: 45864 | AN24: 45865 | AO24: 45866 | AP24: 45867 | AQ24: 45868 | AR24: 45869 | AS24: 45870 | AT24: 45871 | AU24: 45872 | AV24: 45873 | AW24: 45874 | AX24: 45875 | AY24: 45876 | AZ24: 45877 | BA24: 45878 | BB24: 45879 | BC24: 45880 | BD24: 45881 | BE24: 45882 | BF24: 45883 | BG24: 45884 | BH24: 45885 | BI24: 45886 | BJ24: 45887 | BK24: 45888 | BL24: 45889 | BM24: 45890 | BN24: 45891 | BO24: 45892 | BP24: 45893 | BQ24: 45894 | BR24: 45895 | BS24: 45896 | BT24: 45897 | BU24: 45898 | BV24: 45899 | BW24: 45900 | BX24: 45901 | BY24: 45902 | BZ24: 45903 | CA24: 45904 | CB24: 45905 | CC24: 45906 | CD24: 45907 | CE24: 45908 | CF24: 45909 | CG24: 45910 | CH24: 45911 | CI24: 45912 | CJ24: 45913 | CK24: 45914 | CL24: 45915 | CM24: 45916 | CN24: 45917 | CO24: 45918 | CP24: 45919 | CQ24: 45920 | CR24: 45921 | CS24: 45922 | CT24: 45923 | CU24: 45924 | CV24: 45925 | CW24: 45926 | CX24: 45927 | CY24: 45928 | CZ24: 45929 | DA24: 45930 | DB24: 45931 | DC24: 45932 | DD24: 45933 | DE24: 45934 | DF24: 45935 | DG24: 45936 | DH24: 45937 | DI24: 45938 | DJ24: 45939 | DK24: 45940 | DL24: 45941 | DM24: 45942 | DN24: 45943 | DO24: 45944 | DP24: 45945 | DQ24: 45946 | DR24: 45947 | DS24: 45948 | DT24: 45949 | DU24: 45950 | DV24: 45951 | DW24: 45952 | DX24: 45953 | DY24: 45954 | DZ24: 45955 | EA24: 45956 | EB24: 45957 | EC24: 45958 | ED24: 45959 | EE24: 45960 | EF24: 45961 | EG24: 45962 | EH24: 45963 | EI24: 45964 | EJ24: 45965 | EK24: 45966 | EL24: 45967 | EM24: 45968 | EN24: 45969 | EO24: 45970 | EP24: 45971 | EQ24: 45972 | ER24: 45973 | ES24: 45974 | ET24: 45975 | EU24: 45976
A25: КВН | U25: 1 | W25: 3 | Z25: 2 | BI25: 6 | BJ25: 3 | BK25: 2 | BL25: 3 | BM25: 5 | BN25: 1 | BO25: 3 | BP25: 4 | BR25: 2 | BS25: 1 | BU25: 1 | BV25: 3 | BW25: 2 | BX25: 4 | BY25: 1
